Workbook

Sheet _변환기록
A1: 항목 | B1: 내용
A2: 템플릿 | B2: C:\Users\saman\Documents\Codex\2026-05-12\pdf\template.xlsx
A3: 대상면적(㎡) | B3: 10000
A4: 보정계수 직접입력
A5: 보정계수 산식 | B5: =ROUND((D2/1)^(0.6),3)
A6: 비율 | B6: 1
A7: 변환일시 | B7: 2026-05-14 08:32:09
A9: PDF | B9: C:\Users\saman\Desktop\Ai 실습\국토품.pdf
A10: 추출 표 수 | B10: 2
A11: 반영 업무 행 수 | B11: 7
A12: 주의 | B12: 2쪽 표는 예상 양식과 달라 수식 표로 반영하지 못했습니다.

Sheet 국토품_금액
A1: 국토품
A2: 종 별 | B2: 규 격 | C2: 수 량 | D2: 단위 | E2: 총 계 | G2: 노 무 비 | I2: 재 료 비 | K2: 경 비 | M2: 비 고
E3: 단 가 | F3: 금 액 | G3: 단 가 | H3: 금 액 | I3: 단 가 | J3: 금 액 | K3: 단 가 | L3: 금 액 | O3: ■ 엔지니어링 노임단가(2026년_건설)
A4: 가. 직접인건비 | O4: 구 분 | P4: 노 무 비 | Q4: 비 고
A5: 1. 국토품 | C5: 1 | D5: 식 | F5: =H5 | H5: =H16 | O5: 기술사 | P5: 1
A6: 소 계 | F6: =H6 | H6: =SUM(H5:H5) | O6: 특급기술자 | P6: 2
O7: 고급기술자 | P7: 3
A8: 나. 제경비 | B8: (직접인건비)x | D8: 1.1 | F8: =ROUNDDOWN(F6*D8,0) | O8: 중급기술자 | P8: 4
A9: 다. 기술료 | B9: (직접인건비+제경비)x | D9: 0.2 | F9: =INT((F6+F8)*D9) | O9: 초급기술자 | P9: 5
A10: 소 계 | F10: =F8+F9 | O10: 고급숙련기술자 | P10: 6
O11: 중급숙련기술자 | P11: 7
A12: 합 계 | F12: =ROUNDDOWN(F6+F10,0) | O12: 초급숙련기술자 | P12: 8
A13: 적 용 | F13: =ROUNDDOWN(F12,-3) | M13: 단위절사
A14: =A5 | H14: =H15+H22+H27+H32+H39+H45+H48
A15: =A56 | H15: =SUM(H16:H21)
A16: =A57 | F16: =H16 | H16: =H57
A17: =A63 | F17: =H17 | H17: =H63
A18: =A69 | F18: =H18 | H18: =H69
A19: =A75 | F19: =H19 | H19: =H75
A20: =A81 | F20: =H20 | H20: =H81
A21: =A87 | F21: =H21 | H21: =H87
A22: =A94 | H22: =SUM(H23:H26)
A23: =A95 | F23: =H23 | H23: =H95
A24: =A101 | F24: =H24 | H24: =H101
A25: =A107 | F25: =H25 | H25: =H107
A26: =A113 | F26: =H26 | H26: =H113
A27: =A120 | H27: =SUM(H28:H31)
A28: =A121 | F28: =H28 | H28: =H121
A29: =A127 | F29: =H29 | H29: =H127
A30: =A133 | F30: =H30 | H30: =H133
A31: =A139 | F31: =H31 | H31: =H139
A32: =A146 | H32: =SUM(H33:H38)
A33: =A147 | F33: =H33 | H33: =H147
A34: =A153 | F34: =H34 | H34: =H153
A35: =A159 | F35: =H35 | H35: =H159
A36: =A165 | F36: =H36 | H36: =H165
A37: =A171 | F37: =H37 | H37: =H171
A38: =A177 | F38: =H38 | H38: =H177
A39: =A184 | H39: =SUM(H40:H44)
A40: =A185 | F40: =H40 | H40: =H185
...

Sheet 국토품_작업량
A1: <국토품 직접인력 소요작업량 산정>
A2: 10000 | B2: ( | C2: =IF(A2<1000,0.1,ROUND(A2/10000,2)) | D2: 만M2) | E2: 적용
A3: * 대상면적에 대한 작업량 계수 a=(A/1)^(0.6) | E3: a = | F3: =ROUND((ROUND((C2/1)^(0.6),3))*G3,3) | G3: 1
A4: 구분 | B4: 보 정 전 | H4: 보 정 후 | N4: 비 고
B5: 기술사 | C5: 특급 | D5: 고급 | E5: 중급 | F5: 초급 | G5: 보조원 | H5: 기술사 | I5: 특급 | J5: 고급 | K5: 중급 | L5: 초급 | M5: 보조원 | N5: 보정계수
A6: ='국토품_PDF'!A6
A7: ='국토품_PDF'!A7
A8: 1. 조사 및 분석
A9: 1.1 자연환경조사 | B9: 6.9 | C9: 8.6 | D9: 14.5 | E9: 22.8 | F9: 42.4 | H9: =ROUND(B9*N9,2) | I9: =ROUND(C9*N9,2) | J9: =ROUND(D9*N9,2) | K9: =ROUND(E9*N9,2) | L9: =ROUND(F9*N9,2) | N9: =$F$3
A10: 1.2 인문환경조사 | B10: 6.9 | C10: 8.6 | D10: 14.5 | E10: 22.8 | F10: 42.4 | H10: =ROUND(B10*N10,2) | I10: =ROUND(C10*N10,2) | J10: =ROUND(D10*N10,2) | K10: =ROUND(E10*N10,2) | L10: =ROUND(F10*N10,2) | N10: =$F$3
A11: 1.3 산업구조조사 | B11: 6.9 | C11: 8.8 | D11: 14 | E11: 22.3 | F11: 40.3 | H11: =ROUND(B11*N11,2) | I11: =ROUND(C11*N11,2) | J11: =ROUND(D11*N11,2) | K11: =ROUND(E11*N11,2) | L11: =ROUND(F11*N11,2) | N11: =$F$3
A12: 1.4 기반시설조사 | B12: 6.6 | C12: 8.3 | D12: 15 | E12: 22.7 | F12: 40.3 | H12: =ROUND(B12*N12,2) | I12: =ROUND(C12*N12,2) | J12: =ROUND(D12*N12,2) | K12: =ROUND(E12*N12,2) | L12: =ROUND(F12*N12,2) | N12: =$F$3
A13: 1.5 부존자원조사 | B13: 6.7 | C13: 8.3 | D13: 15 | E13: 22.7 | F13: 40.3 | H13: =ROUND(B13*N13,2) | I13: =ROUND(C13*N13,2) | J13: =ROUND(D13*N13,2) | K13: =ROUND(E13*N13,2) | L13: =ROUND(F13*N13,2) | N13: =$F$3
A14: 1.6 유통구조조사 | B14: 7.1 | C14: 9.1 | D14: 14 | E14: 22.3 | F14: 40.3 | H14: =ROUND(B14*N14,2) | I14: =ROUND(C14*N14,2) | J14: =ROUND(D14*N14,2) | K14: =ROUND(E14*N14,2) | L14: =ROUND(F14*N14,2) | N14: =$F$3
A15: 2. 개발여건분석
A16: 2.1 일반여건전망 | B16: 4.5 | C16: 6.1 | D16: 12.9 | E16: 15.2 | F16: 30.8 | H16: =ROUND(B16*N16,2) | I16: =ROUND(C16*N16,2) | J16: =ROUND(D16*N16,2) | K16: =ROUND(E16*N16,2) | L16: =ROUND(F16*N16,2) | N16: =$F$3
A17: 2.2 장기사회경제전망 | B17: 4.7 | C17: 6.6 | D17: 12.2 | E17: 14.3 | F17: 30.8 | H17: =ROUND(B17*N17,2) | I17: =ROUND(C17*N17,2) | J17: =ROUND(D17*N17,2) | K17: =ROUND(E17*N17,2) | L17: =ROUND(F17*N17,2) | N17: =$F$3
A18: 2.3 상위계획과의 상관성 | B18: 4.9 | C18: 6.5 | D18: 12.8 | E18: 15 | F18: 33.3 | H18: =ROUND(B18*N18,2) | I18: =ROUND(C18*N18,2) | J18: =ROUND(D18*N18,2) | K18: =ROUND(E18*N18,2) | L18: =ROUND(F18*N18,2) | N18: =$F$3
A19: 2.4 지역의 발전여건 | B19: 4.5 | C19: 6.1 | D19: 12.9 | E19: 15.2 | F19: 30.8 | H19: =ROUND(B19*N19,2) | I19: =ROUND(C19*N19,2) | J19: =ROUND(D19*N19,2) | K19: =ROUND(E19*N19,2) | L19: =ROUND(F19*N19,2) | N19: =$F$3
A20: 3. 기본구상
A21: 3.1 기본방향설정 | B21: 5.1 | C21: 7 | D21: 14.1 | E21: 14.3 | F21: 22.3 | H21: =ROUND(B21*N21,2) | I21: =ROUND(C21*N21,2) | J21: =ROUND(D21*N21,2) | K21: =ROUND(E21*N21,2) | L21: =ROUND(F21*N21,2) | N21: =$F$3
A22: 3.2 종합개발목표설정 | B22: 4.6 | C22: 6.3 | D22: 15.1 | E22: 16.1 | F22: 22.3 | H22: =ROUND(B22*N22,2) | I22: =ROUND(C22*N22,2) | J22: =ROUND(D22*N22,2) | K22: =ROUND(E22*N22,2) | L22: =ROUND(F22*N22,2) | N22: =$F$3
A23: 3.3 계획지표설정 | B23: 4.9 | C23: 6.8 | D23: 14.1 | E23: 14.3 | F23: 22.3 | H23: =ROUND(B23*N23,2) | I23: =ROUND(C23*N23,2) | J23: =ROUND(D23*N23,2) | K23: =ROUND(E23*N23,2) | L23: =ROUND(F23*N23,2) | N23: =$F$3
A24: 3.4 지역생활권배분 | B24: 5.7 | C24: 7.7 | D24: 14.7 | E24: 15 | F24: 26 | H24: =ROUND(B24*N24,2) | I24: =ROUND(C24*N24,2) | J24: =ROUND(D24*N24,2) | K24: =ROUND(E24*N24,2) | L24: =ROUND(F24*N24,2) | N24: =$F$3
A25: 4. 부문별 개발계획
A26: 4.1 지역별 개발계획 | B26: 10.1 | C26: 13.9 | D26: 27.3 | E26: 36.2 | F26: 45.6 | H26: =ROUND(B26*N26,2) | I26: =ROUND(C26*N26,2) | J26: =ROUND(D26*N26,2) | K26: =ROUND(E26*N26,2) | L26: =ROUND(F26*N26,2) | N26: =$F$3
A27: 4.2 지역경제 개발계획 | B27: 9.4 | C27: 12.7 | D27: 28 | E27: 37.5 | F27: 45.6 | H27: =ROUND(B27*N27,2) | I27: =ROUND(C27*N27,2) | J27: =ROUND(D27*N27,2) | K27: =ROUND(E27*N27,2) | L27: =ROUND(F27*N27,2) | N27: =$F$3
A28: 4.3 교통ㆍ통신 개발계획 | B28: 9.4 | C28: 12.7 | D28: 28 | E28: 37.5 | F28: 45.6 | H28: =ROUND(B28*N28,2) | I28: =ROUND(C28*N28,2) | J28: =ROUND(D28*N28,2) | K28: =ROUND(E28*N28,2) | L28: =ROUND(F28*N28,2) | N28: =$F$3
A29: 4.4 생활복지환경 계획 | B29: 9.3 | C29: 12.6 | D29: 28 | E29: 37.5 | F29: 45.6 | H29: =ROUND(B29*N29,2) | I29: =ROUND(C29*N29,2) | J29: =ROUND(D29*N29,2) | K29: =ROUND(E29*N29,2) | L29: =ROUND(F29*N29,2) | N29: =$F$3
A30: 4.5 환경보전 계획 | B30: 9.9 | C30: 13.4 | D30: 27.9 | E30: 36.8 | F30: 51.1 | H30: =ROUND(B30*N30,2) | I30: =ROUND(C30*N30,2) | J30: =ROUND(D30*N30,2) | K30: =ROUND(E30*N30,2) | L30: =ROUND(F30*N30,2) | N30: =$F$3
A31: 4.6 자원토지 개발계획 | B31: 9.4 | C31: 12.7 | D31: 28 | E31: 37.5 | F31: 45.6 | H31: =ROUND(B31*N31,2) | I31: =ROUND(C31*N31,2) | J31: =ROUND(D31*N31,2) | K31: =ROUND(E31*N31,2) | L31: =ROUND(F31*N31,2) | N31: =$F$3
A32: 5. 계획추진방안
A33: 5.1 지역개발 주요사업선정 | B33: 2.2 | C33: 3.2 | D33: 6.7 | E33: 9.9 | F33: 15.9 | H33: =ROUND(B33*N33,2) | I33: =ROUND(C33*N33,2) | J33: =ROUND(D33*N33,2) | K33: =ROUND(E33*N33,2) | L33: =ROUND(F33*N33,2) | N33: =$F$3
A34: 5.2 단계별 추진계획 | B34: 2.2 | C34: 3.2 | D34: 8.1 | E34: 10.8 | F34: 15.9 | H34: =ROUND(B34*N34,2) | I34: =ROUND(C34*N34,2) | J34: =ROUND(D34*N34,2) | K34: =ROUND(E34*N34,2) | L34: =ROUND(F34*N34,2) | N34: =$F$3
A35: 5.3 집행ㆍ관리계획 | B35: 2.3 | C35: 3.2 | D35: 8.1 | E35: 11.3 | F35: 15.9 | H35: =ROUND(B35*N35,2) | I35: =ROUND(C35*N35,2) | J35: =ROUND(D35*N35,2) | K35: =ROUND(E35*N35,2) | L35: =ROUND(F35*N35,2) | N35: =$F$3
A36: 5.4 행ㆍ재정계획 | B36: 3.2 | C36: 4.7 | D36: 6.7 | E36: 9.9 | F36: 15.9 | H36: =ROUND(B36*N36,2) | I36: =ROUND(C36*N36,2) | J36: =ROUND(D36*N36,2) | K36: =ROUND(E36*N36,2) | L36: =ROUND(F36*N36,2) | N36: =$F$3
A37: 5.5 정책건의 | B37: 3.3 | C37: 4.8 | D37: 6.7 | E37: 9.9 | F37: 15.9 | H37: =ROUND(B37*N37,2) | I37: =ROUND(C37*N37,2) | J37: =ROUND(D37*N37,2) | K37: =ROUND(E37*N37,2) | L37: =ROUND(F37*N37,2) | N37: =$F$3
A38: 6. 성과품 작성
A39: 6.1 보고서 작성 및 편집 | B39: 9.7 | C39: 12.2 | D39: 17.1 | E39: 33.5 | F39: 52.5 | H39: =ROUND(B39*N39,2) | I39: =ROUND(C39*N39,2) | J39: =ROUND(D39*N39,2) | K39: =ROUND(E39*N39,2) | L39: =ROUND(F39*N39,2) | N39: =$F$3
A40: 6.2 관련 도서 작성 | B40: 9.1 | C40: 11.1 | D40: 19.1 | E40: 34.3 | F40: 53.9 | H40: =ROUND(B40*N40,2) | I40: =ROUND(C40*N40,2) | J40: =ROUND(D40*N40,2) | K40: =ROUND(E40*N40,2) | L40: =ROUND(F40*N40,2) | N40: =$F$3
...

Sheet 국토품_PDF
A1: 출처 PDF | B1: C:\Users\saman\Desktop\Ai 실습\국토품.pdf
A2: 쪽수 | B2: 2
A3: 추출일시 | B3: 2026-05-14 08:32:09
A5: 상단 머릿글
A6: 국토계획 제2장 국토 및 지역계획
A7: 라. 투입인원수 산정기준
A9: 표 1
A10: 기본업무 | B10: 단 위 | C10: 기준인원수(인ㆍ일/단위) | H10: 환산 계수
C11: 기술사 | D11: 특 급 기술자 | E11: 고 급 기술자 | F11: 중 급 기술자 | G11: 초 급 기술자
A12: 1. 조사 및 분석
A13: 1.1 자연환경조사 | B13: 500㎢ | C13: 6.9 | D13: 8.6 | E13: 14.5 | F13: 22.8 | G13: 42.4 | H13: ①
A14: 1.2 인문환경조사 | B14: 500㎢ | C14: 6.9 | D14: 8.6 | E14: 14.5 | F14: 22.8 | G14: 42.4 | H14: ①
A15: 1.3 산업구조조사 | B15: 500㎢ | C15: 6.9 | D15: 8.8 | E15: 14.0 | F15: 22.3 | G15: 40.3 | H15: ①
A16: 1.4 기반시설조사 | B16: 500㎢ | C16: 6.6 | D16: 8.3 | E16: 15.0 | F16: 22.7 | G16: 40.3 | H16: ①
A17: 1.5 부존자원조사 | B17: 500㎢ | C17: 6.7 | D17: 8.3 | E17: 15.0 | F17: 22.7 | G17: 40.3 | H17: ①
A18: 1.6 유통구조조사 | B18: 500㎢ | C18: 7.1 | D18: 9.1 | E18: 14.0 | F18: 22.3 | G18: 40.3 | H18: ①
A19: 2. 개발여건분석
A20: 2.1 일반여건전망 | B20: 500㎢ | C20: 4.5 | D20: 6.1 | E20: 12.9 | F20: 15.2 | G20: 30.8 | H20: ①
A21: 2.2 장기사회경제전망 | B21: 500㎢ | C21: 4.7 | D21: 6.6 | E21: 12.2 | F21: 14.3 | G21: 30.8 | H21: ①
A22: 2.3 상위계획과의 상관성 | B22: 500㎢ | C22: 4.9 | D22: 6.5 | E22: 12.8 | F22: 15.0 | G22: 33.3 | H22: ①
A23: 2.4 지역의 발전여건 | B23: 500㎢ | C23: 4.5 | D23: 6.1 | E23: 12.9 | F23: 15.2 | G23: 30.8 | H23: ①
A24: 3. 기본구상
A25: 3.1 기본방향설정 | B25: 500㎢ | C25: 5.1 | D25: 7.0 | E25: 14.1 | F25: 14.3 | G25: 22.3 | H25: ①
A26: 3.2 종합개발목표설정 | B26: 500㎢ | C26: 4.6 | D26: 6.3 | E26: 15.1 | F26: 16.1 | G26: 22.3 | H26: ①
A27: 3.3 계획지표설정 | B27: 500㎢ | C27: 4.9 | D27: 6.8 | E27: 14.1 | F27: 14.3 | G27: 22.3 | H27: ①
A28: 3.4 지역생활권배분 | B28: 500㎢ | C28: 5.7 | D28: 7.7 | E28: 14.7 | F28: 15.0 | G28: 26.0 | H28: ①
A29: 4. 부문별 개발계획
A30: 4.1 지역별 개발계획 | B30: 500㎢ | C30: 10.1 | D30: 13.9 | E30: 27.3 | F30: 36.2 | G30: 45.6 | H30: ①
A31: 4.2 지역경제 개발계획 | B31: 500㎢ | C31: 9.4 | D31: 12.7 | E31: 28.0 | F31: 37.5 | G31: 45.6 | H31: ①
A32: 4.3 교통ㆍ통신 개발계획 | B32: 500㎢ | C32: 9.4 | D32: 12.7 | E32: 28.0 | F32: 37.5 | G32: 45.6 | H32: ①
A33: 4.4 생활복지환경 계획 | B33: 500㎢ | C33: 9.3 | D33: 12.6 | E33: 28.0 | F33: 37.5 | G33: 45.6 | H33: ①
A34: 4.5 환경보전 계획 | B34: 500㎢ | C34: 9.9 | D34: 13.4 | E34: 27.9 | F34: 36.8 | G34: 51.1 | H34: ①
A35: 4.6 자원토지 개발계획 | B35: 500㎢ | C35: 9.4 | D35: 12.7 | E35: 28.0 | F35: 37.5 | G35: 45.6 | H35: ①
A36: 5. 계획추진방안
A37: 5.1 지역개발 주요사업선정 | B37: 500㎢ | C37: 2.2 | D37: 3.2 | E37: 6.7 | F37: 9.9 | G37: 15.9 | H37: ①
A38: 5.2 단계별 추진계획 | B38: 500㎢ | C38: 2.2 | D38: 3.2 | E38: 8.1 | F38: 10.8 | G38: 15.9 | H38: ①
A39: 5.3 집행ㆍ관리계획 | B39: 500㎢ | C39: 2.3 | D39: 3.2 | E39: 8.1 | F39: 11.3 | G39: 15.9 | H39: ①
A40: 5.4 행ㆍ재정계획 | B40: 500㎢ | C40: 3.2 | D40: 4.7 | E40: 6.7 | F40: 9.9 | G40: 15.9 | H40: ①
A41: 5.5 정책건의 | B41: 500㎢ | C41: 3.3 | D41: 4.8 | E41: 6.7 | F41: 9.9 | G41: 15.9 | H41: ①
A42: 6. 성과품 작성
...
