Workbook

Sheet _변환기록
A1: 항목 | B1: 내용
A2: 템플릿 | B2: template.xlsx
A3: 대상면적 | B3: 10000m2
A4: 기준면적 | B4: 10000m2
A5: 승수 | B5: 0.5
A6: 환산계수1 | B6: 1
A7: 환산계수2 | B7: 1
A8: 적용비율 | B8: 1
A9: 노임단가 연도
A10: 변환일시 | B10: 2026-05-14 16:24:30
A12: PDF | B12: C:\Users\saman\Desktop\Ai 실습\_새 폴더\10-1 관광(단)지 계획.pdf
A13: 추출 표 수 | B13: 1
A14: 반영 업무 행 수 | B14: 6

Sheet 10-1 관광(단)지 계획_금액
A1: 10-1 관광(단)지 계획
A2: 종 별 | B2: 규 격 | C2: 수 량 | D2: 단위 | E2: 총 계 | G2: 노 무 비 | I2: 재 료 비 | K2: 경 비 | M2: 비 고
E3: 단 가 | F3: 금 액 | G3: 단 가 | H3: 금 액 | I3: 단 가 | J3: 금 액 | K3: 단 가 | L3: 금 액 | O3: ■ 엔지니어링 노임단가(2026년_건설)
A4: 가. 직접인건비 | O4: 구 분 | P4: 노 무 비 | Q4: 비 고
A5: 1. 관광(단)지 계획 | C5: 1 | D5: 식 | F5: =H5 | H5: =H14 | O5: 기술사 | P5: 467217
A6: 소 계 | F6: =H6 | H6: =SUM(H5:H5) | O6: 특급기술자 | P6: 373353
O7: 고급기술자 | P7: 310884
A8: 나. 제경비 | B8: (직접인건비)x | D8: 1.1 | F8: =ROUNDDOWN(F6*D8,0) | O8: 중급기술자 | P8: 295138
A9: 다. 기술료 | B9: (직접인건비+제경비)x | D9: 0.2 | F9: =INT((F6+F8)*D9) | O9: 초급기술자 | P9: 235459
A10: 소 계 | F10: =F8+F9 | O10: 고급숙련기술자 | P10: 281075
O11: 중급숙련기술자 | P11: 250087
A12: 합 계 | F12: =ROUNDDOWN(F6+F10,0) | O12: 초급숙련기술자 | P12: 218142
A13: 적 용 | F13: =ROUNDDOWN(F12,-3) | M13: 단위절사
A14: =A5 | H14: =H15+H20+H26+H32+H35+H38
A15: =A46 | H15: =SUM(H16:H19)
A16: =A47 | F16: =H16 | H16: =H47
A17: =A53 | F17: =H17 | H17: =H53
A18: =A59 | F18: =H18 | H18: =H59
A19: =A65 | F19: =H19 | H19: =H65
A20: =A72 | H20: =SUM(H21:H25)
A21: =A73 | F21: =H21 | H21: =H73
A22: =A79 | F22: =H22 | H22: =H79
A23: =A85 | F23: =H23 | H23: =H85
A24: =A91 | F24: =H24 | H24: =H91
A25: =A97 | F25: =H25 | H25: =H97
A26: =A104 | H26: =SUM(H27:H31)
A27: =A105 | F27: =H27 | H27: =H105
A28: =A111 | F28: =H28 | H28: =H111
A29: =A117 | F29: =H29 | H29: =H117
A30: =A123 | F30: =H30 | H30: =H123
A31: =A129 | F31: =H31 | H31: =H129
A32: =A136 | H32: =SUM(H33:H34)
A33: =A137 | F33: =H33 | H33: =H137
A34: =A143 | F34: =H34 | H34: =H143
A35: =A150 | H35: =SUM(H36:H37)
A36: =A151 | F36: =H36 | H36: =H151
A37: =A157 | F37: =H37 | H37: =H157
A38: =A164 | H38: =SUM(H39:H44)
A39: =A165 | F39: =H39 | H39: =H165
A40: =A171 | F40: =H40 | H40: =H171
...

Sheet 10-1 관광(단)지 계획_작업량
A1: <10-1 관광(단)지 계획 직접인력 소요작업량 산정>
A2: 대상면적 | B2: 10000 | C2: 기준면적 | D2: 10000 | E2: 승수 | F2: 0.5 | G2: 환산계수1 | H2: 1 | I2: 환산계수2 | J2: 1 | K2: 적용비율 | L2: 1
A3: 산식 : a=(대상면적/기준면적)^(승수) | B3: =IF(D2=0,0,ROUND((B2/D2)^F2,2)) | G3: =ROUND(B3*H2*J2*L2,2) | H3: (적용보정계수)
A4: 구분 | B4: 보 정 전 | H4: 보 정 후 | N4: 비 고
B5: 기술사 | C5: 특급 | D5: 고급 | E5: 중급 | F5: 초급 | G5: 보조원 | H5: 기술사 | I5: 특급 | J5: 고급 | K5: 중급 | L5: 초급 | M5: 보조원 | N5: 보정계수
A6: 1. 조사분석
A7: 1.1 개발여건분석 | B7: 1 | C7: 2 | D7: 3.9 | E7: 5.6 | F7: 8.2 | H7: =ROUND(B7*N7,2) | I7: =ROUND(C7*N7,2) | J7: =ROUND(D7*N7,2) | K7: =ROUND(E7*N7,2) | L7: =ROUND(F7*N7,2) | N7: =$G$3
A8: 1.2 입지여건분석 | B8: 1.2 | C8: 2.6 | D8: 4.9 | E8: 6.2 | F8: 8.6 | H8: =ROUND(B8*N8,2) | I8: =ROUND(C8*N8,2) | J8: =ROUND(D8*N8,2) | K8: =ROUND(E8*N8,2) | L8: =ROUND(F8*N8,2) | N8: =$G$3
A9: 1.3 관광자원분석 | B9: 1.3 | C9: 2.2 | D9: 5 | E9: 6.3 | F9: 8.7 | H9: =ROUND(B9*N9,2) | I9: =ROUND(C9*N9,2) | J9: =ROUND(D9*N9,2) | K9: =ROUND(E9*N9,2) | L9: =ROUND(F9*N9,2) | N9: =$G$3
A10: 1.4 종합분석 | B10: 1.6 | C10: 3.2 | D10: 6.5 | E10: 7.6 | F10: 10.7 | H10: =ROUND(B10*N10,2) | I10: =ROUND(C10*N10,2) | J10: =ROUND(D10*N10,2) | K10: =ROUND(E10*N10,2) | L10: =ROUND(F10*N10,2) | N10: =$G$3
A11: 2. 기본구상
A12: 2.1 개발방향설정 | B12: 1.7 | C12: 4.5 | D12: 7.2 | E12: 7.6 | F12: 10.4 | H12: =ROUND(B12*N12,2) | I12: =ROUND(C12*N12,2) | J12: =ROUND(D12*N12,2) | K12: =ROUND(E12*N12,2) | L12: =ROUND(F12*N12,2) | N12: =$G$3
A13: 2.2 수급분석 및 예측 | B13: 2.2 | C13: 6 | D13: 9.6 | E13: 9.4 | F13: 12.5 | H13: =ROUND(B13*N13,2) | I13: =ROUND(C13*N13,2) | J13: =ROUND(D13*N13,2) | K13: =ROUND(E13*N13,2) | L13: =ROUND(F13*N13,2) | N13: =$G$3
A14: 2.3 공급규모 산정 | B14: 1.8 | C14: 4.8 | D14: 8.3 | E14: 9 | F14: 12.5 | H14: =ROUND(B14*N14,2) | I14: =ROUND(C14*N14,2) | J14: =ROUND(D14*N14,2) | K14: =ROUND(E14*N14,2) | L14: =ROUND(F14*N14,2) | N14: =$G$3
A15: 2.4 공간구성체계 | B15: 1.6 | C15: 4.6 | D15: 7.7 | E15: 8.6 | F15: 12.3 | H15: =ROUND(B15*N15,2) | I15: =ROUND(C15*N15,2) | J15: =ROUND(D15*N15,2) | K15: =ROUND(E15*N15,2) | L15: =ROUND(F15*N15,2) | N15: =$G$3
A16: 2.5 동선체계구상 | B16: 1.7 | C16: 5 | D16: 8.1 | E16: 8 | F16: 11.1 | H16: =ROUND(B16*N16,2) | I16: =ROUND(C16*N16,2) | J16: =ROUND(D16*N16,2) | K16: =ROUND(E16*N16,2) | L16: =ROUND(F16*N16,2) | N16: =$G$3
A17: 3. 기본계획
A18: 3.1 토지이용계획 | B18: 3 | C18: 6.7 | D18: 11.1 | E18: 12.5 | F18: 14.4 | H18: =ROUND(B18*N18,2) | I18: =ROUND(C18*N18,2) | J18: =ROUND(D18*N18,2) | K18: =ROUND(E18*N18,2) | L18: =ROUND(F18*N18,2) | N18: =$G$3
A19: 3.2 교통동선계획 | B19: 2.5 | C19: 5.7 | D19: 9.3 | E19: 10.5 | F19: 12.2 | H19: =ROUND(B19*N19,2) | I19: =ROUND(C19*N19,2) | J19: =ROUND(D19*N19,2) | K19: =ROUND(E19*N19,2) | L19: =ROUND(F19*N19,2) | N19: =$G$3
A20: 3.3 시설물배치계획 | B20: 3.1 | C20: 5.7 | D20: 9.9 | E20: 10.1 | F20: 12.8 | H20: =ROUND(B20*N20,2) | I20: =ROUND(C20*N20,2) | J20: =ROUND(D20*N20,2) | K20: =ROUND(E20*N20,2) | L20: =ROUND(F20*N20,2) | N20: =$G$3
A21: 3.4 식재계획 | B21: 2.1 | C21: 5 | D21: 7.7 | E21: 9.4 | F21: 13.7 | H21: =ROUND(B21*N21,2) | I21: =ROUND(C21*N21,2) | J21: =ROUND(D21*N21,2) | K21: =ROUND(E21*N21,2) | L21: =ROUND(F21*N21,2) | N21: =$G$3
A22: 3.5 공급처리시설계획 | B22: 2.5 | C22: 5.6 | D22: 8.6 | E22: 10.3 | F22: 12.6 | H22: =ROUND(B22*N22,2) | I22: =ROUND(C22*N22,2) | J22: =ROUND(D22*N22,2) | K22: =ROUND(E22*N22,2) | L22: =ROUND(F22*N22,2) | N22: =$G$3
A23: 4. 집행(사업)계획
A24: 4.1 개발추진계획 | B24: 1.8 | C24: 4.5 | D24: 6.3 | E24: 7.7 | F24: 9.5 | H24: =ROUND(B24*N24,2) | I24: =ROUND(C24*N24,2) | J24: =ROUND(D24*N24,2) | K24: =ROUND(E24*N24,2) | L24: =ROUND(F24*N24,2) | N24: =$G$3
A25: 4.2 관리운영계획 | B25: 1.5 | C25: 4.1 | D25: 6 | E25: 7.7 | F25: 9.2 | H25: =ROUND(B25*N25,2) | I25: =ROUND(C25*N25,2) | J25: =ROUND(D25*N25,2) | K25: =ROUND(E25*N25,2) | L25: =ROUND(F25*N25,2) | N25: =$G$3
A26: 5. 성과품 작성
A27: 5.1 보고서 | B27: 1.4 | C27: 2.8 | D27: 5.4 | E27: 8.5 | F27: 10.6 | H27: =ROUND(B27*N27,2) | I27: =ROUND(C27*N27,2) | J27: =ROUND(D27*N27,2) | K27: =ROUND(E27*N27,2) | L27: =ROUND(F27*N27,2) | N27: =$G$3
A28: 5.2 관련 도서 | B28: 2.7 | C28: 5.6 | D28: 10.7 | E28: 16.9 | F28: 21.4 | H28: =ROUND(B28*N28,2) | I28: =ROUND(C28*N28,2) | J28: =ROUND(D28*N28,2) | K28: =ROUND(E28*N28,2) | L28: =ROUND(F28*N28,2) | N28: =$G$3
A29: 6. 기술협의
A30: 6.1 주민의견청취ㆍ주민공람 | B30: 3 | C30: 3 | D30: 3 | E30: 6 | F30: 6 | H30: =ROUND(B30*N30,2) | I30: =ROUND(C30*N30,2) | J30: =ROUND(D30*N30,2) | K30: =ROUND(E30*N30,2) | L30: =ROUND(F30*N30,2) | N30: 1
A31: 6.2 주민설명회ㆍ공청회 | B31: 3 | C31: 3 | D31: 3 | E31: 6 | F31: 6 | H31: =ROUND(B31*N31,2) | I31: =ROUND(C31*N31,2) | J31: =ROUND(D31*N31,2) | K31: =ROUND(E31*N31,2) | L31: =ROUND(F31*N31,2) | N31: 1
A32: 6.3 관계기관협의 | B32: 4 | C32: 4 | D32: 4 | E32: 8 | F32: 8 | H32: =ROUND(B32*N32,2) | I32: =ROUND(C32*N32,2) | J32: =ROUND(D32*N32,2) | K32: =ROUND(E32*N32,2) | L32: =ROUND(F32*N32,2) | N32: 1
A33: 6.4 협의의견 조정ㆍ반영 | B33: 10 | C33: 10 | D33: 10 | E33: 13 | F33: 13 | H33: =ROUND(B33*N33,2) | I33: =ROUND(C33*N33,2) | J33: =ROUND(D33*N33,2) | K33: =ROUND(E33*N33,2) | L33: =ROUND(F33*N33,2) | N33: 1
A34: 6.5 의회의견 청취 | B34: 2 | C34: 2 | D34: 2 | E34: 4 | F34: 4 | H34: =ROUND(B34*N34,2) | I34: =ROUND(C34*N34,2) | J34: =ROUND(D34*N34,2) | K34: =ROUND(E34*N34,2) | L34: =ROUND(F34*N34,2) | N34: 1
A35: 6.6 위원회 자문ㆍ심의지원 | B35: 4 | C35: 4 | D35: 4 | E35: 8 | F35: 8 | H35: =ROUND(B35*N35,2) | I35: =ROUND(C35*N35,2) | J35: =ROUND(D35*N35,2) | K35: =ROUND(E35*N35,2) | L35: =ROUND(F35*N35,2) | N35: 1
A36: 소 계 | B36: =SUM(B6:B35) | C36: =SUM(C6:C35) | D36: =SUM(D6:D35) | E36: =SUM(E6:E35) | F36: =SUM(F6:F35) | H36: =SUM(H6:H35) | I36: =SUM(I6:I35) | J36: =SUM(J6:J35) | K36: =SUM(K6:K35) | L36: =SUM(L6:L35)
A37: ='10-1 관광(단)지 계획_PDF'!A44
A38: ='10-1 관광(단)지 계획_PDF'!A45
A39: ='10-1 관광(단)지 계획_PDF'!A46
A40: ='10-1 관광(단)지 계획_PDF'!A47
...

Sheet 10-1 관광(단)지 계획_PDF
A1: 출처 PDF | B1: C:\Users\saman\Desktop\Ai 실습\_새 폴더\10-1 관광(단)지 계획.pdf
A2: 쪽수 | B2: 1
A3: 추출일시 | B3: 2026-05-14 16:24:30
A5: 상단 머릿글
A6: 국토계획 제10장 관광레저분야
A7: 라. 투입인원수 산정기준
A9: 표 1
A10: 기본업무 | B10: 단위 | C10: 기준인원수(인ㆍ일/단위) | H10: 환산 계수 | I10: 보정 계수
C11: 기술사 | D11: 특 급 기술자 | E11: 고 급 기술자 | F11: 중 급 기술자 | G11: 초 급 기술자 | I11: ㉮ | J11: ㉯
A12: 1. 조사분석
A13: 1.1 개발여건분석 | B13: 20만㎡ | C13: 1.0 | D13: 2.0 | E13: 3.9 | F13: 5.6 | G13: 8.2 | H13: ① | I13: ● | J13: ●
A14: 1.2 입지여건분석 | B14: 20만㎡ | C14: 1.2 | D14: 2.6 | E14: 4.9 | F14: 6.2 | G14: 8.6 | H14: ① | I14: ● | J14: ●
A15: 1.3 관광자원분석 | B15: 20만㎡ | C15: 1.3 | D15: 2.2 | E15: 5.0 | F15: 6.3 | G15: 8.7 | H15: ① | I15: ● | J15: ●
A16: 1.4 종합분석 | B16: 20만㎡ | C16: 1.6 | D16: 3.2 | E16: 6.5 | F16: 7.6 | G16: 10.7 | H16: ① | I16: ● | J16: ●
A17: 2. 기본구상
A18: 2.1 개발방향설정 | B18: 20만㎡ | C18: 1.7 | D18: 4.5 | E18: 7.2 | F18: 7.6 | G18: 10.4 | H18: ① | I18: ● | J18: ●
A19: 2.2 수급분석 및 예측 | B19: 20만㎡ | C19: 2.2 | D19: 6.0 | E19: 9.6 | F19: 9.4 | G19: 12.5 | H19: ① | I19: ● | J19: ●
A20: 2.3 공급규모 산정 | B20: 20만㎡ | C20: 1.8 | D20: 4.8 | E20: 8.3 | F20: 9.0 | G20: 12.5 | H20: ① | I20: ● | J20: ●
A21: 2.4 공간구성체계 | B21: 20만㎡ | C21: 1.6 | D21: 4.6 | E21: 7.7 | F21: 8.6 | G21: 12.3 | H21: ① | I21: ● | J21: ●
A22: 2.5 동선체계구상 | B22: 20만㎡ | C22: 1.7 | D22: 5.0 | E22: 8.1 | F22: 8.0 | G22: 11.1 | H22: ① | I22: ● | J22: ●
A23: 3. 기본계획
A24: 3.1 토지이용계획 | B24: 20만㎡ | C24: 3.0 | D24: 6.7 | E24: 11.1 | F24: 12.5 | G24: 14.4 | H24: ① | I24: ● | J24: ●
A25: 3.2 교통동선계획 | B25: 20만㎡ | C25: 2.5 | D25: 5.7 | E25: 9.3 | F25: 10.5 | G25: 12.2 | H25: ① | I25: ● | J25: ●
A26: 3.3 시설물배치계획 | B26: 20만㎡ | C26: 3.1 | D26: 5.7 | E26: 9.9 | F26: 10.1 | G26: 12.8 | H26: ① | I26: ● | J26: ●
A27: 3.4 식재계획 | B27: 20만㎡ | C27: 2.1 | D27: 5.0 | E27: 7.7 | F27: 9.4 | G27: 13.7 | H27: ① | I27: ● | J27: ●
A28: 3.5 공급처리시설계획 | B28: 20만㎡ | C28: 2.5 | D28: 5.6 | E28: 8.6 | F28: 10.3 | G28: 12.6 | H28: ① | I28: ● | J28: ●
A29: 4. 집행(사업)계획
A30: 4.1 개발추진계획 | B30: 20만㎡ | C30: 1.8 | D30: 4.5 | E30: 6.3 | F30: 7.7 | G30: 9.5 | H30: ① | I30: ● | J30: ●
A31: 4.2 관리운영계획 | B31: 20만㎡ | C31: 1.5 | D31: 4.1 | E31: 6.0 | F31: 7.7 | G31: 9.2 | H31: ① | I31: ● | J31: ●
A32: 5. 성과품 작성
A33: 5.1 보고서 | B33: 20만㎡ | C33: 1.4 | D33: 2.8 | E33: 5.4 | F33: 8.5 | G33: 10.6 | H33: ① | I33: ● | J33: ●
A34: 5.2 관련 도서 | B34: 20만㎡ | C34: 2.7 | D34: 5.6 | E34: 10.7 | F34: 16.9 | G34: 21.4 | H34: ① | I34: ● | J34: ●
A35: 6. 기술협의
A36: 6.1 주민의견청취ㆍ주민공람 | B36: 식 | C36: 3.0 | D36: 3.0 | E36: 3.0 | F36: 6.0 | G36: 6.0 | H36: ②
A37: 6.2 주민설명회ㆍ공청회 | B37: 식 | C37: 3.0 | D37: 3.0 | E37: 3.0 | F37: 6.0 | G37: 6.0 | H37: ②
A38: 6.3 관계기관협의 | B38: 식 | C38: 4.0 | D38: 4.0 | E38: 4.0 | F38: 8.0 | G38: 8.0 | H38: ②
A39: 6.4 협의의견 조정ㆍ반영 | B39: 식 | C39: 10.0 | D39: 10.0 | E39: 10.0 | F39: 13.0 | G39: 13.0 | H39: ②
A40: 6.5 의회의견 청취 | B40: 식 | C40: 2.0 | D40: 2.0 | E40: 2.0 | F40: 4.0 | G40: 4.0 | H40: ②
A41: 6.6 위원회 자문ㆍ심의지원 | B41: 식 | C41: 4.0 | D41: 4.0 | E41: 4.0 | F41: 8.0 | G41: 8.0 | H41: ②
A43: 주기
...
