Workbook

Sheet _변환기록
A1: 항목 | B1: 내용
A2: 템플릿 | B2: template.xlsx
A3: 대상면적(㎡) | B3: 10000
A4: 보정계수 직접입력
A5: 보정계수 산식 | B5: =ROUND((D2/1)^(0.6),3)
A6: 비율 | B6: 1
A7: 변환일시 | B7: 2026-05-13 10:16:49
A9: PDF | B9: C:\Users\saman\Desktop\Ai 실습\_새 폴더\12-6 실시계획인가.pdf
A10: 추출 표 수 | B10: 1
A11: 반영 업무 행 수 | B11: 5

Sheet 12-6 실시계획인가_금액
A1: 12-6 실시계획인가
A2: 종 별 | B2: 규 격 | C2: 수 량 | D2: 단위 | E2: 총 계 | G2: 재 료 비 | I2: 노 무 비 | K2: 경 비 | M2: 비 고
E3: 단 가 | F3: 금 액 | G3: 단 가 | H3: 금 액 | I3: 단 가 | J3: 금 액 | K3: 단 가 | L3: 금 액 | O3: ■ 엔지니어링 노임단가(2026년_건설)
A4: 가. 직접인건비 | O4: 구 분 | P4: 노 무 비 | Q4: 비 고
A5: 1. 실시계획인가 | C5: 1 | D5: 식 | J5: =J15 | O5: 기술사 | P5: 467217
A6: 소 계 | J6: =SUM(J5:J5) | O6: 특급기술자 | P6: 373353
O7: 고급기술자 | P7: 310884
A8: 나. 제 경 비 | E8: (직접인건비)x | G8: 1.1 | J8: =ROUNDDOWN(J6*G8,0) | O8: 중급기술자 | P8: 295138
A9: 다. 기 술 료 | E9: (직접인건비+제경비)x | G9: 0.2 | J9: =INT((J6+J8)*G9) | O9: 초급기술자 | P9: 235459
A10: 소 계 | J10: =SUM(J8:J9) | O10: 고급숙련기술자 | P10: 281075
O11: 중급숙련기술자 | P11: 250087
A12: 합 계 | J12: =ROUNDDOWN(J6+J10,0) | O12: 초급숙련기술자 | P12: 218142
A13: 적 용 | J13: =ROUNDDOWN(J12,-5)
A15: =A5 | J15: =J16+J23+J30+J37+J44
A16: ='12-6 실시계획인가_작업량'!A9 | J16: =SUM(J17:J21)
A17: 기 술 사 | C17: ='12-6 실시계획인가_작업량'!H9 | D17: 인 | I17: =$P$5 | J17: =ROUNDDOWN(I17*C17,0)
A18: 특급기술자 | C18: ='12-6 실시계획인가_작업량'!I9 | D18: 인 | I18: =$P$6 | J18: =ROUNDDOWN(I18*C18,0)
A19: 고급기술자 | C19: ='12-6 실시계획인가_작업량'!J9 | D19: 인 | I19: =$P$7 | J19: =ROUNDDOWN(I19*C19,0)
A20: 중급기술자 | C20: ='12-6 실시계획인가_작업량'!K9 | D20: 인 | I20: =$P$8 | J20: =ROUNDDOWN(I20*C20,0)
A21: 초급기술자 | C21: ='12-6 실시계획인가_작업량'!L9 | D21: 인 | I21: =$P$9 | J21: =ROUNDDOWN(I21*C21,0)
A23: ='12-6 실시계획인가_작업량'!A10 | J23: =SUM(J24:J28)
A24: 기 술 사 | C24: ='12-6 실시계획인가_작업량'!H10 | D24: 인 | I24: =$P$5 | J24: =ROUNDDOWN(I24*C24,0)
A25: 특급기술자 | C25: ='12-6 실시계획인가_작업량'!I10 | D25: 인 | I25: =$P$6 | J25: =ROUNDDOWN(I25*C25,0)
A26: 고급기술자 | C26: ='12-6 실시계획인가_작업량'!J10 | D26: 인 | I26: =$P$7 | J26: =ROUNDDOWN(I26*C26,0)
A27: 중급기술자 | C27: ='12-6 실시계획인가_작업량'!K10 | D27: 인 | I27: =$P$8 | J27: =ROUNDDOWN(I27*C27,0)
A28: 초급기술자 | C28: ='12-6 실시계획인가_작업량'!L10 | D28: 인 | I28: =$P$9 | J28: =ROUNDDOWN(I28*C28,0)
A30: ='12-6 실시계획인가_작업량'!A11 | J30: =SUM(J31:J35)
A31: 기 술 사 | C31: ='12-6 실시계획인가_작업량'!H11 | D31: 인 | I31: =$P$5 | J31: =ROUNDDOWN(I31*C31,0)
A32: 특급기술자 | C32: ='12-6 실시계획인가_작업량'!I11 | D32: 인 | I32: =$P$6 | J32: =ROUNDDOWN(I32*C32,0)
A33: 고급기술자 | C33: ='12-6 실시계획인가_작업량'!J11 | D33: 인 | I33: =$P$7 | J33: =ROUNDDOWN(I33*C33,0)
A34: 중급기술자 | C34: ='12-6 실시계획인가_작업량'!K11 | D34: 인 | I34: =$P$8 | J34: =ROUNDDOWN(I34*C34,0)
A35: 초급기술자 | C35: ='12-6 실시계획인가_작업량'!L11 | D35: 인 | I35: =$P$9 | J35: =ROUNDDOWN(I35*C35,0)
A37: ='12-6 실시계획인가_작업량'!A12 | J37: =SUM(J38:J42)
A38: 기 술 사 | C38: ='12-6 실시계획인가_작업량'!H12 | D38: 인 | I38: =$P$5 | J38: =ROUNDDOWN(I38*C38,0)
A39: 특급기술자 | C39: ='12-6 실시계획인가_작업량'!I12 | D39: 인 | I39: =$P$6 | J39: =ROUNDDOWN(I39*C39,0)
A40: 고급기술자 | C40: ='12-6 실시계획인가_작업량'!J12 | D40: 인 | I40: =$P$7 | J40: =ROUNDDOWN(I40*C40,0)
A41: 중급기술자 | C41: ='12-6 실시계획인가_작업량'!K12 | D41: 인 | I41: =$P$8 | J41: =ROUNDDOWN(I41*C41,0)
A42: 초급기술자 | C42: ='12-6 실시계획인가_작업량'!L12 | D42: 인 | I42: =$P$9 | J42: =ROUNDDOWN(I42*C42,0)
A44: ='12-6 실시계획인가_작업량'!A13 | J44: =SUM(J45:J49)
A45: 기 술 사 | C45: ='12-6 실시계획인가_작업량'!H13 | D45: 인 | I45: =$P$5 | J45: =ROUNDDOWN(I45*C45,0)
...

Sheet 12-6 실시계획인가_작업량
A1: <12-6 실시계획인가 직접인력 소요작업량 산정>
A2: 10000 | B2: ( | C2: =IF(A2<1000,0.1,ROUND(A2/10000,2)) | D2: 만M2) | E2: 적용
A3: * 대상면적에 대한 작업량 계수 a=(A/1)^(0.6) | E3: a = | F3: =ROUND((ROUND((C2/1)^(0.6),3))*G3,3) | G3: 1
A4: 구분 | B4: 보 정 전 | H4: 보 정 후 | N4: 비 고
B5: 기술사 | C5: 특급 | D5: 고급 | E5: 중급 | F5: 초급 | G5: 보조원 | H5: 기술사 | I5: 특급 | J5: 고급 | K5: 중급 | L5: 초급 | M5: 보조원 | N5: 보정계수
A6: ='12-6 실시계획인가_PDF'!A6
A7: ='12-6 실시계획인가_PDF'!A7
A8: ='12-6 실시계획인가_PDF'!A8
A9: 1. 실시계획 승인도서 작성 | B9: 0.7 | C9: 0.6 | D9: 1.3 | E9: 1.3 | F9: 3.5 | H9: =ROUND(B9*N9,2) | I9: =ROUND(C9*N9,2) | J9: =ROUND(D9*N9,2) | K9: =ROUND(E9*N9,2) | L9: =ROUND(F9*N9,2) | N9: =$F$3
A10: 2. 보고서 작성 및 편집 | B10: 0.4 | C10: 0.9 | D10: 1.8 | E10: 1.6 | F10: 2.8 | H10: =ROUND(B10*N10,2) | I10: =ROUND(C10*N10,2) | J10: =ROUND(D10*N10,2) | K10: =ROUND(E10*N10,2) | L10: =ROUND(F10*N10,2) | N10: =$F$3
A11: 3. 관련도서 작성 | B11: 0.6 | C11: 0.8 | D11: 1.4 | E11: 1.6 | F11: 4.2 | H11: =ROUND(B11*N11,2) | I11: =ROUND(C11*N11,2) | J11: =ROUND(D11*N11,2) | K11: =ROUND(E11*N11,2) | L11: =ROUND(F11*N11,2) | N11: =$F$3
A12: 4. 주민공람 | B12: 2.4 | C12: 2.5 | D12: 2.6 | E12: 4.7 | F12: 5.1 | H12: =ROUND(B12*N12,2) | I12: =ROUND(C12*N12,2) | J12: =ROUND(D12*N12,2) | K12: =ROUND(E12*N12,2) | L12: =ROUND(F12*N12,2) | N12: 1
A13: 5. 관계기관 협의 | B13: 2.4 | C13: 2.5 | D13: 2.6 | E13: 4.7 | F13: 5.1 | H13: =ROUND(B13*N13,2) | I13: =ROUND(C13*N13,2) | J13: =ROUND(D13*N13,2) | K13: =ROUND(E13*N13,2) | L13: =ROUND(F13*N13,2) | N13: 1
A14: 소 계 | B14: =SUM(B9:B13) | C14: =SUM(C9:C13) | D14: =SUM(D9:D13) | E14: =SUM(E9:E13) | F14: =SUM(F9:F13) | H14: =SUM(H9:H13) | I14: =SUM(I9:I13) | J14: =SUM(J9:J13) | K14: =SUM(K9:K13) | L14: =SUM(L9:L13)
A15: ='12-6 실시계획인가_PDF'!A20
A16: ='12-6 실시계획인가_PDF'!A21
A17: ='12-6 실시계획인가_PDF'!A22
A18: ='12-6 실시계획인가_PDF'!A23
A19: ='12-6 실시계획인가_PDF'!A24
A20: ='12-6 실시계획인가_PDF'!A25
A21: ='12-6 실시계획인가_PDF'!A26
A22: ='12-6 실시계획인가_PDF'!A27
A23: ='12-6 실시계획인가_PDF'!A28

Sheet 12-6 실시계획인가_PDF
A1: 출처 PDF | B1: C:\Users\saman\Desktop\Ai 실습\_새 폴더\12-6 실시계획인가.pdf
A2: 쪽수 | B2: 1
A3: 추출일시 | B3: 2026-05-13 10:16:49
A5: 상단 머릿글
A6: 국토계획 제12장 사업관리
A7: 라. 투입인원수 산정기준
A8: (1) 도시ㆍ군계획시설사업 실시계획인가
A10: 표 1
A11: 기본업무 | B11: 단 위 | C11: 기준인원수(인ㆍ일/단위) | H11: 환산 계수
C12: 기술사 | D12: 특 급 기술자 | E12: 고 급 기술자 | F12: 중 급 기술자 | G12: 초 급 기술자
A13: 1. 실시계획 승인도서 작성 | B13: 1만㎡ | C13: 0.7 | D13: 0.6 | E13: 1.3 | F13: 1.3 | G13: 3.5 | H13: ①
A14: 2. 보고서 작성 및 편집 | B14: 1만㎡ | C14: 0.4 | D14: 0.9 | E14: 1.8 | F14: 1.6 | G14: 2.8 | H14: ①
A15: 3. 관련도서 작성 | B15: 1만㎡ | C15: 0.6 | D15: 0.8 | E15: 1.4 | F15: 1.6 | G15: 4.2 | H15: ①
A16: 4. 주민공람 | B16: 식 | C16: 2.4 | D16: 2.5 | E16: 2.6 | F16: 4.7 | G16: 5.1 | H16: ②
A17: 5. 관계기관 협의 | B17: 식 | C17: 2.4 | D17: 2.5 | E17: 2.6 | F17: 4.7 | G17: 5.1 | H17: ②
A19: 주기
A20: 주 1) 토지적성평가, 사업인정의제협의, 농지ㆍ산지전용협의, 국공유지무상귀속 등은 별도 산정한다.
A21: 2) 지하안전영향평가 등 각종 영향성검토 및 각종 영향평가업무는 별도 산정한다.
A22: 3) 기본설계 및 실시설계, 측량, 토질조사 등 설계 및 조사, 시험은 별도 산정한다.
A23: 3) 실시계획인가는 도시ㆍ군관리계획 결정 이후 도시ㆍ군계획시설사업 시행 시 적용한다.
A24: 4) 실시계획인가 업무내용 중 보고서 작성 및 편집은 필요시 적용한다.
A25: 5) 해당 시설의 종류에 따라 면적(面的)시설 또는 선적(線的)시설로 구분하고, 구분에 따라 규모를 산정하며 기준면적(거리)은
A26: 1만㎡(1.0km)를 원칙으로 한다.
A27: 6) 기술협의 단위‘식’이란 인허가 신청 후 승인 고시까지의 업무이며, 고시 이후에는 별도 산정한다.
A28: 7) 위원회 자문ㆍ심의지원 중 공동심의, 통합심의일 경우 50%를 가산한다.
