Workbook
Name ______tt1: "tt1"
Name _____tt1: "tt1"
Name ____tt1: "tt1"
Name ___tt1: "tt1"
Name __DemandLoad: TRUE
Name __tt1: "tt1"
Name _1_3_0Crite: #REF!
Name _1_3_0Crite: #REF!
Name _1_3_0Crite: #REF!
Name _1_3_0Crite: #REF!
Name _2_3_0Criteria: #REF!
Name _2_3_0Criteria: #REF!
Name _2_3_0Criteria: #REF!
Name _2_3_0Criteria: #REF!
Name _3_3__Crite: #REF!
Name _3_3__Crite: #REF!
Name _3_3__Crite: #REF!
Name _3_3__Crite: #REF!
Name _4_3__Criteria: #REF!
Name _4_3__Criteria: #REF!
Name _4_3__Criteria: #REF!
Name _4_3__Criteria: #REF!
Name _5G_0Extr: #REF!
Name _5G_0Extr: #REF!
Name _5G_0Extr: #REF!
Name _5G_0Extr: #REF!
Name _6G_0Extract: #REF!
Name _6G_0Extract: #REF!
Name _6G_0Extract: #REF!
Name _6G_0Extract: #REF!
Name _7G__Extr: #REF!
Name _7G__Extr: #REF!
Name _7G__Extr: #REF!
Name _7G__Extr: #REF!
Name _8G__Extract: #REF!
Name _8G__Extract: #REF!
Name _8G__Extract: #REF!
Name _8G__Extract: #REF!
Name _O: "○"
Name _tt1: "tt1"
Name asp두께: 0.15
Name MTTR: 528
Name PQ점수: "Dialog Frame 1"
Name ㄱ기계: #REF!
Name ㄱ기계: #REF!
Name ㄱ기계: #REF!
Name ㄱ기계: #REF!
Name ㄱ기초일위: #REF!
Name ㄱ기초일위: #REF!
Name ㄱ기초일위: #REF!
Name ㄱ기초일위: #REF!
Name ㄱ부표: #REF!
Name ㄱ부표: #REF!
Name ㄱ부표: #REF!
Name ㄱ부표: #REF!
Name ㄱ일위: #REF!
Name ㄱ일위: #REF!
Name ㄱ일위: #REF!
Name ㄱ일위: #REF!
Name ㄱ임시이동: #REF!

Sheet 갑지
A3: 세종시 정원도시 기본계획 수립 및 기본설계 용역
A4: 설 계 내 역 서
A10: 2025. 06.
A14: 세종특별자치시
B17: 2025년 6월
A18: 세종시 정원도시 기본계획 수립 및 기본설계 용역
C20: ◈ 과업대상 : | E20: 세종시
C21: ◈ 과업내용 : | E21: 정원도시 기본계획 수립, 정원 조성 기본설계 용역
E22: (조사 분석, 기본구상, 기본계획, 집행계획, 기본설계 등)
B24: 총 용 역 비 : | D24: =내역!F31 -> 497310000 | G24: ="(일금"&TEXT(D24,"[DBnum4]G/표준")&"원)" -> (일금사억구천칠백삼십일만원)
G26: 위계약자 | H26: 주 소 : | I26: 경기도 과천시 별양상가 3로 5(별양동)
H27: 상 호 : | I27: ㈜ 삼 안
H28: 대표자 : | I28: 최 동 식 (인)
H29: 주 소 : | I29: 충청남도 당진시 고대면 성산로 464
H30: 상 호 : | I30: ㈜ 한맥기술
H31: 대표자 : | I31: 이 경 훈 (인)
H32: 주 소 : | I32: 경기도 안양시 동안구 부림로 121
H33: 상 호 : | I33: ㈜ 이 산
H34: 대표자 : | I34: 이 원 찬 (인)

Sheet 내역
A1: 용 역 원 가 계 산 서
A2: 공 종 | B2: 규 격 | C2: 수 량 | D2: 단위 | E2: 계 | G2: 재 료 비 | I2: 노 무 비 | K2: 경 비 | M2: 비 고
E3: 단 가 | F3: 금 액 | G3: 단 가 | H3: 금 액 | I3: 단 가 | J3: 금 액 | K3: 단 가 | L3: 금 액
A4: 1. 정원도시 기본계획 수립(실비정액가산방식) | F4: =SUM(F5,F12,F17,F18) -> 2.747e+08
A5: 1. 직접인건비 | F5: =H5+J5+L5 -> 92719050 | H5: =SUM(H6:H11) -> 0 | J5: =SUM(J6:J11) -> 92719050 | L5: =SUM(L6:L11) -> 0 | M5: 낙찰적용
A6: 1. 조사분석 | C6: 1 | D6: 식 | F6: =H6+J6+L6 -> 10167653 | H6: =H34 -> 0 | J6: =J34 -> 10167653
A7: 2. 기본구상 | C7: 1 | D7: 식 | F7: =H7+J7+L7 -> 24334711 | H7: =H39 -> 0 | J7: =J39 -> 24334711
A8: 3. 기본계획 | C8: 1 | D8: 식 | F8: =H8+J8+L8 -> 35590868 | H8: =H46 -> 0 | J8: =J46 -> 35590868
A9: 4. 집행(사업)계획 | C9: 1 | D9: 식 | F9: =H9+J9+L9 -> 8974309 | H9: =H47 -> 0 | J9: =J53 -> 8974309
A10: 5. 성과품 작성 | C10: 1 | D10: 식 | F10: =H10+J10+L10 -> 3153718 | H10: =H57 -> 0 | J10: =J57 -> 3153718
A11: 6. 기술협의 | C11: 1 | D11: 식 | F11: =H11+J11+L11 -> 10497791 | H11: =H61 -> 0 | J11: =J61 -> 10497791
A12: 2. 직접경비 | F12: =H12+J12+L12 -> 41048000 | L12: =SUM(L13:L16) -> 41048000
A13: 1. 인쇄비 | C13: 1 | D13: 식 | F13: =H13+J13+L13 -> 3368000 | L13: ='1-2.직접경비(기정)'!F6 -> 3368000
A14: 2. 주민설명회 경비 | C14: 1 | D14: 식 | F14: =H14+J14+L14 -> 2700000 | L14: ='1-2.직접경비(기정)'!F7 -> 2700000
A15: 3. 포럼 및 워크숍 경비 | C15: 1 | D15: 식 | F15: =H15+J15+L15 -> 21380000 | L15: ='1-2.직접경비(기정)'!F8 -> 21380000 | M15: 사후정산
A16: 4. 자문회의비 | C16: 1 | D16: 식 | F16: =H16+J16+L16 -> 13600000 | L16: ='1-2.직접경비(기정)'!F9 -> 13600000 | M16: 사후정산
A17: 3. 제경비 | B17: 직접인건비의 | C17: 110 | D17: % | F17: =H17+J17+L17 -> 1.0199095e+08 | L17: =ROUNDDOWN(F5*C17/100,0)-3.5 -> 1.0199095e+08
A18: 4. 기술료 | B18: (직접인건비+ 제경비)의 | C18: 20 | D18: % | F18: =H18+J18+L18 -> 38942000 | L18: =ROUNDDOWN((F5+F17)*C18/100,0) -> 38942000
A20: 2. 기본설계(공사비요율방식) | F20: =SUM(F21) -> 177400000 | M20: 낙찰적용
A21: 1. 기본설계 | F21: =SUM(F22:F23) -> 177400000 | H21: =SUM(H24:H31) -> 0 | J21: =SUM(J24:J31) -> 0 | L21: =SUM(L24:L31) -> 0
A22: 1. 기본설계 | C22: 1 | D22: 식 | F22: ='2-1.기본설계'!E13 -> 171600000 | H22: =H46 -> 0
A23: 2. 직접경비 | C23: 1 | D23: 식 | F23: ='2-1.기본설계'!E20 -> 5800000
A25: 소 계 | F25: =SUM(F4,F20) -> 4.521e+08
A27: 손해배상공제보험료(해당없음) | F27: 0 | M27: 미대상
A29: 부가가치세 | C29: 10 | D29: % | F29: =INT(F25*C29%) -> 45210000 | Q29: 593860000
A31: 합 계 | F31: =ROUNDDOWN(F25+F29,0) -> 497310000 | P31: =Q31/Q29 -> 0.83741959 | Q31: 497310000
A32: 1. 정원도시 기본계획 수립 | Q32: =Q31/1.1 -> 4.521e+08
A33: Ｉ. 직접인건비
A34: 1. 조사분석 | F34: =H34+J34+L34 -> 10167653 | H34: =SUM(H35:H40) -> 0 | J34: =SUM(J35:J37) -> 10167653 | L34: =SUM(L35:L40) -> 0
A35: 1.1 자연환경 | C35: 1 | D35: 식 | F35: =H35+J35+L35 -> 3177995.9 | H35: =INT($C35*G35) -> 0 | J35: ='1-1.직접인건비(일위대가)'!J10 -> 3177995.9 | L35: =INT($C35*K35) -> 0 | M35: ='1-1.직접인건비(일위대가)'!M3 -> 산근1
A36: 1.2 인문환경 | C36: 1 | D36: 식 | F36: =H36+J36+L36 -> 3396657 | H36: =INT($C36*G36) -> 0 | J36: ='1-1.직접인건비(일위대가)'!J19 -> 3396657 | L36: =INT($C36*K36) -> 0 | M36: ='1-1.직접인건비(일위대가)'!M12 -> 산근2
A37: 1.3 종합분석 | C37: 1 | D37: 식 | F37: =H37+J37+L37 -> 3593000 | H37: =INT($C37*G37) -> 0 | J37: ='1-1.직접인건비(일위대가)'!J28 -> 3593000 | L37: =INT($C37*K37) -> 0 | M37: ='1-1.직접인건비(일위대가)'!M21 -> 산근3
A39: 2. 기본구상 | F39: =H39+J39+L39 -> 24334711 | H39: =SUM(H41:H43) -> 0 | J39: =SUM(J40:J44) -> 24334711 | L39: =SUM(L41:L43) -> 0
A40: 2.1 조성방향 설정 | C40: 1 | D40: 식 | F40: =H40+J40+L40 -> 4473160 | H40: =INT($C40*G40) -> 0 | J40: ='1-1.직접인건비(일위대가)'!J37 -> 4473160 | L40: =INT($C40*K40) -> 0 | M40: ='1-1.직접인건비(일위대가)'!M30 -> 산근4
A41: 2.2 계획지표 설정 | C41: 1 | D41: 식 | F41: =H41+J41+L41 -> 4349707 | H41: =INT($C41*G41) -> 0 | J41: ='1-1.직접인건비(일위대가)'!J46 -> 4349707 | L41: =INT($C41*K41) -> 0 | M41: ='1-1.직접인건비(일위대가)'!M39 -> 산근5
A42: 2.3 토지이용체계구상 | C42: 1 | D42: 식 | F42: =H42+J42+L42 -> 5079023 | H42: =INT($C42*G42) -> 0 | J42: ='1-1.직접인건비(일위대가)'!J55 -> 5079023 | L42: =INT($C42*K42) -> 0 | M42: ='1-1.직접인건비(일위대가)'!M48 -> 산근6
A43: 2.4 동선체계구상 | C43: 1 | D43: 식 | F43: =H43+J43+L43 -> 5079023 | H43: =INT($C43*G43) -> 0 | J43: ='1-1.직접인건비(일위대가)'!J64 -> 5079023 | L43: =INT($C43*K43) -> 0 | M43: ='1-1.직접인건비(일위대가)'!M57 -> 산근7
A44: 2.5 정원 주제 및 규모설정 | C44: 1 | D44: 식 | F44: =H44+J44+L44 -> 5353798 | H44: =INT($C44*G44) -> 0 | J44: ='1-1.직접인건비(일위대가)'!F73 -> 5353798 | L44: =INT($C44*K44) -> 0 | M44: 산근8
A46: 3. 기본계획 | F46: =H46+J46+L46 -> 35590868 | H46: =SUM(H47:H50) -> 0 | J46: =SUM(J47:J51) -> 35590868 | L46: =SUM(L47:L50) -> 0
A47: 3.1 토지이용계획 | C47: 1 | D47: 식 | F47: =H47+J47+L47 -> 7361781 | H47: =INT($C47*G47) -> 0 | J47: ='1-1.직접인건비(일위대가)'!J82 -> 7361781 | L47: =INT($C47*K47) -> 0 | M47: 산근9
...

Sheet 용역비산출(간지)
A1: 용 역 비 산 출

Sheet 1-1.직접인건비(일위대가)
A1: 공 종 | B1: 규 격 | C1: 수 량 | D1: 단위 | E1: 합 계 | G1: 재 료 비 | I1: 노 무 비 | K1: 경 비 | M1: 비 고
E2: 단 가 | F2: 금 액 | G2: 단 가 | H2: 금 액 | I2: 단 가 | J2: 금 액 | K2: 단 가 | L2: 금 액
A3: [제 1 호표] 자연환경 분석 | M3: 산근1
A4: 기술사 | C4: ='산출근거(소요인원수 산출)'!E28 -> 0.48126218 | D4: 인 | E4: =G4+I4+K4 -> 452718 | F4: =H4+J4+L4 -> 217876.05 | I4: ='산출근거(소요인원수 산출)'!D10 -> 452718 | J4: =I4*C4 -> 217876.05 | L4: =INT($C4*K4) -> 0
A5: 특급기술자 | C5: ='산출근거(소요인원수 산출)'!G28 -> 1.1229451 | D5: 인 | E5: =G5+I5+K5 -> 358273 | F5: =H5+J5+L5 -> 402320.9 | I5: ='산출근거(소요인원수 산출)'!F10 -> 358273 | J5: =I5*C5 -> 402320.9 | L5: =INT($C5*K5) -> 0
A6: 고급기술자 | C6: ='산출근거(소요인원수 산출)'!I28 -> 2.3528373 | D6: 인 | E6: =G6+I6+K6 -> 300980 | F6: =H6+J6+L6 -> 708156.97 | I6: ='산출근거(소요인원수 산출)'!H10 -> 300980 | J6: =I6*C6 -> 708156.97 | L6: =INT($C6*K6) -> 0
A7: 중급기술자 | C7: ='산출근거(소요인원수 산출)'!K28 -> 3.1014674 | D7: 인 | E7: =G7+I7+K7 -> 284046 | F7: =H7+J7+L7 -> 880959.39 | I7: ='산출근거(소요인원수 산출)'!J10 -> 284046 | J7: =I7*C7 -> 880959.39 | L7: =INT($C7*K7) -> 0
A8: 초급기술자 | C8: ='산출근거(소요인원수 산출)'!M28 -> 4.3313596 | D8: 인 | E8: =G8+I8+K8 -> 223644 | F8: =H8+J8+L8 -> 968682.58 | I8: ='산출근거(소요인원수 산출)'!L10 -> 223644 | J8: =I8*C8 -> 968682.58 | L8: =INT($C8*K8) -> 0
A9: 보조원 | C9: ='산출근거(소요인원수 산출)'!O28 -> 0 | D9: 인 | E9: =G9+I9+K9 -> 204392 | F9: =H9+J9+L9 -> 0 | I9: ='산출근거(소요인원수 산출)'!N10 -> 204392 | J9: =I9*C9 -> 0 | L9: =SUM(L4:L8) -> 0
A10: 소계 | F10: =SUM(F4:F9) -> 3177995.9 | J10: =SUM(J4:J9) -> 3177995.9
A12: [제 2 호표] 인문환경 분석 | M12: 산근2
A13: 기술사 | C13: ='산출근거(소요인원수 산출)'!E29 -> 0.48126218 | D13: 인 | E13: =G13+I13+K13 -> 452718 | F13: =H13+J13+L13 -> 217876 | H13: =INT($C13*G13) -> 0 | I13: ='산출근거(소요인원수 산출)'!D10 -> 452718 | J13: =INT($C13*I13) -> 217876 | L13: =INT($C13*K13) -> 0
A14: 특급기술자 | C14: ='산출근거(소요인원수 산출)'!G29 -> 1.2298922 | D14: 인 | E14: =G14+I14+K14 -> 358273 | F14: =H14+J14+L14 -> 440637 | H14: =INT($C14*G14) -> 0 | I14: ='산출근거(소요인원수 산출)'!F10 -> 358273 | J14: =INT($C14*I14) -> 440637 | L14: =INT($C14*K14) -> 0
A15: 고급기술자 | C15: ='산출근거(소요인원수 산출)'!I29 -> 2.3528373 | D15: 인 | E15: =G15+I15+K15 -> 300980 | F15: =H15+J15+L15 -> 708156 | H15: =INT($C15*G15) -> 0 | I15: ='산출근거(소요인원수 산출)'!H10 -> 300980 | J15: =INT($C15*I15) -> 708156 | L15: =INT($C15*K15) -> 0
A16: 중급기술자 | C16: ='산출근거(소요인원수 산출)'!K29 -> 3.3153617 | D16: 인 | E16: =G16+I16+K16 -> 284046 | F16: =H16+J16+L16 -> 941715 | H16: =INT($C16*G16) -> 0 | I16: ='산출근거(소요인원수 산출)'!J10 -> 284046 | J16: =INT($C16*I16) -> 941715 | L16: =INT($C16*K16) -> 0
A17: 초급기술자 | C17: ='산출근거(소요인원수 산출)'!M29 -> 4.8660953 | D17: 인 | E17: =G17+I17+K17 -> 223644 | F17: =H17+J17+L17 -> 1088273 | I17: ='산출근거(소요인원수 산출)'!L10 -> 223644 | J17: =INT($C17*I17) -> 1088273
A18: 보조원 | C18: ='산출근거(소요인원수 산출)'!O29 -> 0 | D18: 인 | E18: =G18+I18+K18 -> 204392 | F18: =H18+J18+L18 -> 0 | H18: =INT($C18*G18) -> 0 | I18: ='산출근거(소요인원수 산출)'!N10 -> 204392 | J18: =INT($C18*I18) -> 0 | L18: =INT($C18*K18) -> 0
A19: 소계 | F19: =SUM(F13:F18) -> 3396657 | J19: =SUM(J13:J18) -> 3396657
A21: [제 3 호표] 종합분석 | M21: 산근3
A22: 기술사 | C22: ='산출근거(소요인원수 산출)'!E30 -> 0.6416829 | D22: 인 | E22: =G22+I22+K22 -> 452718 | F22: =H22+J22+L22 -> 290501 | I22: ='산출근거(소요인원수 산출)'!D10 -> 452718 | J22: =INT($C22*I22) -> 290501
A23: 특급기술자 | C23: ='산출근거(소요인원수 산출)'!G30 -> 1.390313 | D23: 인 | E23: =G23+I23+K23 -> 358273 | F23: =H23+J23+L23 -> 498111 | I23: ='산출근거(소요인원수 산출)'!F10 -> 358273 | J23: =INT($C23*I23) -> 498111
A24: 고급기술자 | C24: ='산출근거(소요인원수 산출)'!I30 -> 2.6202052 | D24: 인 | E24: =G24+I24+K24 -> 300980 | F24: =H24+J24+L24 -> 788629 | I24: ='산출근거(소요인원수 산출)'!H10 -> 300980 | J24: =INT($C24*I24) -> 788629
A25: 중급기술자 | C25: ='산출근거(소요인원수 산출)'!K30 -> 3.4757824 | D25: 인 | E25: =G25+I25+K25 -> 284046 | F25: =H25+J25+L25 -> 987282 | I25: ='산출근거(소요인원수 산출)'!J10 -> 284046 | J25: =INT($C25*I25) -> 987282
A26: 초급기술자 | C26: ='산출근거(소요인원수 산출)'!M30 -> 4.5987275 | D26: 인 | E26: =G26+I26+K26 -> 223644 | F26: =H26+J26+L26 -> 1028477 | I26: ='산출근거(소요인원수 산출)'!L10 -> 223644 | J26: =INT($C26*I26) -> 1028477
A27: 보조원 | C27: ='산출근거(소요인원수 산출)'!O30 -> 0 | D27: 인 | E27: =G27+I27+K27 -> 204392 | F27: =H27+J27+L27 -> 0 | I27: ='산출근거(소요인원수 산출)'!N10 -> 204392 | J27: =INT($C27*I27) -> 0
A28: 소계 | F28: =SUM(F22:F27) -> 3593000 | J28: =SUM(J22:J27) -> 3593000
A30: [제 4 호표] 조성방향 설정 | M30: 산근4
A31: 기술사 | C31: ='산출근거(소요인원수 산출)'!E32 -> 0.90905078 | D31: 인 | E31: =G31+I31+K31 -> 452718 | F31: =H31+J31+L31 -> 411543 | I31: ='산출근거(소요인원수 산출)'!D10 -> 452718 | J31: =INT($C31*I31) -> 411543
A32: 특급기술자 | C32: ='산출근거(소요인원수 산출)'!G32 -> 2.2458902 | D32: 인 | E32: =G32+I32+K32 -> 358273 | F32: =H32+J32+L32 -> 804641 | I32: ='산출근거(소요인원수 산출)'!F10 -> 358273 | J32: =INT($C32*I32) -> 804641
A33: 고급기술자 | C33: ='산출근거(소요인원수 산출)'!I32 -> 3.5827295 | D33: 인 | E33: =G33+I33+K33 -> 300980 | F33: =H33+J33+L33 -> 1078329 | I33: ='산출근거(소요인원수 산출)'!H10 -> 300980 | J33: =INT($C33*I33) -> 1078329
A34: 중급기술자 | C34: ='산출근거(소요인원수 산출)'!K32 -> 3.7966238 | D34: 인 | E34: =G34+I34+K34 -> 284046 | F34: =H34+J34+L34 -> 1078415 | I34: ='산출근거(소요인원수 산출)'!J10 -> 284046 | J34: =INT($C34*I34) -> 1078415
A35: 초급기술자 | C35: ='산출근거(소요인원수 산출)'!M32 -> 4.9195689 | D35: 인 | E35: =G35+I35+K35 -> 223644 | F35: =H35+J35+L35 -> 1100232 | I35: ='산출근거(소요인원수 산출)'!L10 -> 223644 | J35: =INT($C35*I35) -> 1100232
A36: 보조원 | C36: 0 | D36: 인 | E36: =G36+I36+K36 -> 204392 | F36: =H36+J36+L36 -> 0 | I36: ='산출근거(소요인원수 산출)'!N10 -> 204392 | J36: =INT($C36*I36) -> 0
A37: 소계 | F37: =SUM(F31:F36) -> 4473160 | J37: =SUM(J31:J36) -> 4473160
A39: [제 5 호표] 계획지표 설정 | M39: 산근5
A40: 기술사 | C40: ='산출근거(소요인원수 산출)'!E33 -> 0.80210363 | D40: 인 | E40: =G40+I40+K40 -> 452718 | F40: =H40+J40+L40 -> 363126 | I40: ='산출근거(소요인원수 산출)'!D10 -> 452718 | J40: =INT($C40*I40) -> 363126
A41: 특급기술자 | C41: ='산출근거(소요인원수 산출)'!G33 -> 2.4063109 | D41: 인 | E41: =G41+I41+K41 -> 358273 | F41: =H41+J41+L41 -> 862116 | I41: ='산출근거(소요인원수 산출)'!F10 -> 358273 | J41: =INT($C41*I41) -> 862116
A42: 고급기술자 | C42: ='산출근거(소요인원수 산출)'!I33 -> 3.5827295 | D42: 인 | E42: =G42+I42+K42 -> 300980 | F42: =H42+J42+L42 -> 1078329 | I42: ='산출근거(소요인원수 산출)'!H10 -> 300980 | J42: =INT($C42*I42) -> 1078329
A43: 중급기술자 | C43: ='산출근거(소요인원수 산출)'!K33 -> 3.5827295 | D43: 인 | E43: =G43+I43+K43 -> 284046 | F43: =H43+J43+L43 -> 1017659 | I43: ='산출근거(소요인원수 산출)'!J10 -> 284046 | J43: =INT($C43*I43) -> 1017659
A44: 초급기술자 | C44: ='산출근거(소요인원수 산출)'!M33 -> 4.5987275 | D44: 인 | E44: =G44+I44+K44 -> 223644 | F44: =H44+J44+L44 -> 1028477 | I44: ='산출근거(소요인원수 산출)'!L10 -> 223644 | J44: =INT($C44*I44) -> 1028477
...

Sheet 산출근거(소요인원수 산출)
A1: 직 접 인 건 비 산 출 근 거
B3: 1. 내역산출근거
B4: - 2024년 국토계획 표준품셈(제11장 주제형사업 및 특화분야 11-1 주제형사업)
B6: 2. 2025년 건설기술자 노임단가(2024 엔지니어링업체 임금실태 조사결과 적용)
P7: (단위:원)
B8: 구 분 | D8: 기술사 | F8: 특급기술자 | H8: 고급기술자 | J8: 중급기술자 | L8: 초급기술자 | N8: 보조원 | P8: 비 고
B9: 엔지니어링협회단가 | D9: =노임단가!B3 -> 452718 | F9: =노임단가!B4 -> 358273 | H9: =노임단가!B5 -> 300980 | J9: =노임단가!B6 -> 284046 | L9: =노임단가!B7 -> 223644 | N9: =노임단가!B10 -> 204392
B10: 내역단가 | C10: 1 | D10: =D9*$C$10 -> 452718 | F10: =F9*$C$10 -> 358273 | H10: =H9*$C$10 -> 300980 | J10: =J9*$C$10 -> 284046 | L10: =L9*$C$10 -> 223644 | N10: =N9*$C$10 -> 204392
B12: 3. 환산계수
B13: 정원도시 조성 기본계획
B14: 계획면적 | C14: ='산출근거(계획면적 산정)'!F14 -> 50000 | D14: ㎡ | F14: ※ '계획면적 산정' 참조
B15: 기준면적 | C15: 100000 | D15: ㎡
B16: 환산계수 | C16: β = (계획면적/기준면적)^0.6 | D16: =(C14/C15)^0.6 -> 0.65975396 | F16: ※ 소수점 둘째 자리에서 반올림
S17: 0.81050784
B18: 4. 보정계수 | S18: =내역!F31-내역!Q31 -> 0
B19: 정원도시 조성 기본계획
B20: 보정계수 | C20: 대상지 성격: 내륙형 | D20: 1 | F20: ※ 내륙형 1.0 / 도시형 1.1 / 해안호수형 1.2
B21: 낙찰률적용 | D21: =S17 -> 0.81050784
B24: 5. 소요인원수 산출
B25: 구분 | C25: 업무내용 | D25: 기술자(인ㆍ일) | P25: 비고
D26: 기술사 | F26: 특급 | H26: 고급 | J26: 중급 | L26: 초급 | N26: 보조원
D27: 기준 인원수 | E27: 투입 인원수 | F27: 기준 인원수 | G27: 투입 인원수 | H27: 기준 인원수 | I27: 투입 인원수 | J27: 기준 인원수 | K27: 투입 인원수 | L27: 기준 인원수 | M27: 투입 인원수 | N27: 기준 인원수 | O27: 투입 인원수
B28: 1. 조사분석 | C28: 자연환경 | D28: 0.9 | E28: =D28*$D$16*$D$20*$D$21 -> 0.48126218 | F28: 2.1 | G28: =F28*$D$16*$D$20*$D$21 -> 1.1229451 | H28: 4.4 | I28: =H28*$D$16*$D$20*$D$21 -> 2.3528373 | J28: 5.8 | K28: =J28*$D$16*$D$20*$D$21 -> 3.1014674 | L28: 8.1 | M28: =L28*$D$16*$D$20*$D$21 -> 4.3313596 | N28: 0 | O28: =N28*$D$16*$D$20*$D$21 -> 0
C29: 인문환경 | D29: 0.9 | E29: =D29*$D$16*$D$20*$D$21 -> 0.48126218 | F29: 2.3 | G29: =F29*$D$16*$D$20*$D$21 -> 1.2298922 | H29: 4.4 | I29: =H29*$D$16*$D$20*$D$21 -> 2.3528373 | J29: 6.2 | K29: =J29*$D$16*$D$20*$D$21 -> 3.3153617 | L29: 9.1 | M29: =L29*$D$16*$D$20*$D$21 -> 4.8660953 | N29: 0 | O29: =N29*$D$16*$D$20*$D$21 -> 0
C30: 종합분석 | D30: 1.2 | E30: =D30*$D$16*$D$20*$D$21 -> 0.6416829 | F30: 2.6 | G30: =F30*$D$16*$D$20*$D$21 -> 1.390313 | H30: 4.9 | I30: =H30*$D$16*$D$20*$D$21 -> 2.6202052 | J30: 6.5 | K30: =J30*$D$16*$D$20*$D$21 -> 3.4757824 | L30: 8.6 | M30: =L30*$D$16*$D$20*$D$21 -> 4.5987275 | N30: 0 | O30: =N30*$D$16*$D$20*$D$21 -> 0
C31: 소 계 | D31: =SUM(D28:D30) -> 3 | E31: =ROUNDDOWN(SUM(E28:E30),2) -> 1.6 | F31: =SUM(F28:F30) -> 7 | G31: =ROUNDDOWN(SUM(G28:G30),2) -> 3.74 | H31: =SUM(H28:H30) -> 13.7 | I31: =ROUNDDOWN(SUM(I28:I30),2) -> 7.32 | J31: =SUM(J28:J30) -> 18.5 | K31: =ROUNDDOWN(SUM(K28:K30),2) -> 9.89 | L31: =SUM(L28:L30) -> 25.8 | M31: =ROUNDDOWN(SUM(M28:M30),2) -> 13.79 | N31: =SUM(N28:N30) -> 0 | O31: =ROUNDDOWN(SUM(O28:O30),2) -> 0
B32: 2. 기본구상 | C32: 조성방향 설정 | D32: 1.7 | E32: =D32*$D$16*$D$20*$D$21 -> 0.90905078 | F32: 4.2 | G32: =F32*$D$16*$D$20*$D$21 -> 2.2458902 | H32: 6.7 | I32: =H32*$D$16*$D$20*$D$21 -> 3.5827295 | J32: 7.1 | K32: =J32*$D$16*$D$20*$D$21 -> 3.7966238 | L32: 9.2 | M32: =L32*$D$16*$D$20*$D$21 -> 4.9195689 | N32: 0 | O32: =N32*D16 -> 0
C33: 계획지표 설정 | D33: 1.5 | E33: =D33*$D$16*$D$20*$D$21 -> 0.80210363 | F33: 4.5 | G33: =F33*$D$16*$D$20*$D$21 -> 2.4063109 | H33: 6.7 | I33: =H33*$D$16*$D$20*$D$21 -> 3.5827295 | J33: 6.7 | K33: =J33*$D$16*$D$20*$D$21 -> 3.5827295 | L33: 8.6 | M33: =L33*$D$16*$D$20*$D$21 -> 4.5987275 | N33: 0 | O33: =N33*D16 -> 0
C34: 토지이용체계구상 | D34: 1.6 | E34: =D34*$D$16*$D$20*$D$21 -> 0.8555772 | F34: 4.9 | G34: =F34*$D$16*$D$20*$D$21 -> 2.6202052 | H34: 7.4 | I34: =H34*$D$16*$D$20*$D$21 -> 3.9570446 | J34: 8.6 | K34: =J34*$D$16*$D$20*$D$21 -> 4.5987275 | L34: 10.5 | M34: =L34*$D$16*$D$20*$D$21 -> 5.6147254 | N34: 0 | O34: =N34*D16 -> 0
C35: 동선체계구상 | D35: 1.6 | E35: =D35*$D$16*$D$20*$D$21 -> 0.8555772 | F35: 4.9 | G35: =F35*$D$16*$D$20*$D$21 -> 2.6202052 | H35: 7.4 | I35: =H35*$D$16*$D$20*$D$21 -> 3.9570446 | J35: 8.6 | K35: =J35*$D$16*$D$20*$D$21 -> 4.5987275 | L35: 10.5 | M35: =L35*$D$16*$D$20*$D$21 -> 5.6147254 | N35: 0 | O35: =N35*D16 -> 0
C36: 정원 주제 및 규모 설정 | D36: 1.8 | E36: =D36*$D$16*$D$20*$D$21 -> 0.96252435 | F36: 5.4 | G36: =F36*$D$16*$D$20*$D$21 -> 2.8875731 | H36: 8.4 | I36: =H36*$D$16*$D$20*$D$21 -> 4.4917803 | J36: 8.4 | K36: =J36*$D$16*$D$20*$D$21 -> 4.4917803 | L36: 10.5 | M36: =L36*$D$16*$D$20*$D$21 -> 5.6147254 | N36: 0 | O36: =N36*D16 -> 0
C37: 소 계 | D37: =SUM(D32:D36) -> 8.2 | E37: =ROUNDDOWN(SUM(E32:E36),2) -> 4.38 | F37: =SUM(F32:F36) -> 23.9 | G37: =ROUNDDOWN(SUM(G32:G36),2) -> 12.78 | H37: =SUM(H32:H36) -> 36.6 | I37: =ROUNDDOWN(SUM(I32:I36),2) -> 19.57 | J37: =SUM(J32:J36) -> 39.4 | K37: =ROUNDDOWN(SUM(K32:K36),2) -> 21.06 | L37: =SUM(L32:L36) -> 49.3 | M37: =ROUNDDOWN(SUM(M32:M36),2) -> 26.36 | N37: =SUM(N32:N36) -> 0 | O37: =ROUNDDOWN(SUM(O32:O36),2) -> 0
B38: 3. 기본계획 | C38: 토지이용계획 | D38: 2.7 | E38: =D38*$D$16*$D$20*$D$21 -> 1.4437865 | F38: 7.1 | G38: =F38*$D$16*$D$20*$D$21 -> 3.7966238 | H38: 10.8 | I38: =H38*$D$16*$D$20*$D$21 -> 5.7751461 | J38: 12.9 | K38: =J38*$D$16*$D$20*$D$21 -> 6.8980912 | L38: 13.8 | M38: =L38*$D$16*$D$20*$D$21 -> 7.3793534 | N38: 0 | O38: =N38*D16 -> 0
C39: 이동 동선 및 테마 설정 | D39: 2.7 | E39: =D39*$D$16*$D$20*$D$21 -> 1.4437865 | F39: 6.7 | G39: =F39*$D$16*$D$20*$D$21 -> 3.5827295 | H39: 10.8 | I39: =H39*$D$16*$D$20*$D$21 -> 5.7751461 | J39: 12.5 | K39: =J39*$D$16*$D$20*$D$21 -> 6.6841969 | L39: 17.7 | M39: =L39*$D$16*$D$20*$D$21 -> 9.4648228 | N39: 0 | O39: =N39*D16 -> 0
C40: 시설배치계획 | D40: 3.1 | E40: =D40*$D$16*$D$20*$D$21 -> 1.6576808 | F40: 6.2 | G40: =F40*$D$16*$D$20*$D$21 -> 3.3153617 | H40: 10.8 | I40: =H40*$D$16*$D$20*$D$21 -> 5.7751461 | J40: 10.6 | K40: =J40*$D$16*$D$20*$D$21 -> 5.668199 | L40: 13.6 | M40: =L40*$D$16*$D$20*$D$21 -> 7.2724062 | N40: 0 | O40: =N40*D16 -> 0
C41: 식재계획 | D41: 2.3 | E41: =D41*$D$16*$D$20*$D$21 -> 1.2298922 | F41: 5.9 | G41: =F41*$D$16*$D$20*$D$21 -> 3.1549409 | H41: 9.8 | I41: =H41*$D$16*$D$20*$D$21 -> 5.2404104 | J41: 11.1 | K41: =J41*$D$16*$D$20*$D$21 -> 5.9355668 | L41: 15.7 | M41: =L41*$D$16*$D$20*$D$21 -> 8.3953513 | N41: 0 | O41: =N41*D16 -> 0
C42: 공급처리계획 | D42: 2.4 | E42: =D42*$D$16*$D$20*$D$21 -> 1.2833658 | F42: 6.5 | G42: =F42*$D$16*$D$20*$D$21 -> 3.4757824 | H42: 9.7 | I42: =H42*$D$16*$D$20*$D$21 -> 5.1869368 | J42: 11.9 | K42: =J42*$D$16*$D$20*$D$21 -> 6.3633554 | L42: 13.4 | M42: =L42*$D$16*$D$20*$D$21 -> 7.1654591 | N42: 0 | O42: =N42*D16 -> 0
C43: 소 계 | D43: =SUM(D38:D42) -> 13.2 | E43: =ROUNDDOWN(SUM(E38:E42),2) -> 7.05 | F43: =SUM(F38:F42) -> 32.4 | G43: =ROUNDDOWN(SUM(G38:G42),2) -> 17.32 | H43: =SUM(H38:H42) -> 51.9 | I43: =ROUNDDOWN(SUM(I38:I42),2) -> 27.75 | J43: =SUM(J38:J42) -> 59 | K43: =ROUNDDOWN(SUM(K38:K42),2) -> 31.54 | L43: =SUM(L38:L42) -> 74.2 | M43: =ROUNDDOWN(SUM(M38:M42),2) -> 39.67 | N43: =SUM(N38:N42) -> 0 | O43: =ROUNDDOWN(SUM(O38:O42),2) -> 0
B44: 4. 집행(사업) 계획 | C44: 조성추진계획 | D44: 1.7 | E44: =D44*$D$16*$D$20*$D$21 -> 0.90905078 | F44: 4.6 | G44: =F44*$D$16*$D$20*$D$21 -> 2.4597845 | H44: 6.6 | I44: =H44*$D$16*$D$20*$D$21 -> 3.529256 | J44: 7.9 | K44: =J44*$D$16*$D$20*$D$21 -> 4.2244124 | L44: 8.7 | M44: =L44*$D$16*$D$20*$D$21 -> 4.652201 | N44: 0 | O44: =N44*D20 -> 0
C45: 관리운영계획 | D45: 1.4 | E45: =D45*$D$16*$D$20*$D$21 -> 0.74863005 | F45: 4 | G45: =F45*$D$16*$D$20*$D$21 -> 2.138943 | H45: 5.9 | I45: =H45*$D$16*$D$20*$D$21 -> 3.1549409 | J45: 7.9 | K45: =J45*$D$16*$D$20*$D$21 -> 4.2244124 | L45: 9.4 | M45: =L45*$D$16*$D$20*$D$21 -> 5.0265161 | N45: 0 | O45: =N45*D22 -> 0
...

Sheet 1-2.직접경비(기정)
B1: 직 접 경 비 산 출 내 역 서
B3: Ⅱ. 직접경비
B4: 구 분 | F4: 금액(원) | N4: =F8+F9 -> 34980000
B5: 계 | F5: =SUM(F6:K9) -> 41048000 | N5: =N4*0.1 -> 3498000
B6: 인쇄비 | F6: =K13 -> 3368000 | N6: =N4+N5 -> 38478000
B7: 주민설명회 경비 | F7: =K20 -> 2700000
B8: 포럼 및 워크숍 경비 | F8: =K27 -> 21380000
B9: 자문회의비 | F9: =K46 -> 13600000
B11: Ⅱ-1. 인쇄비
B12: 구 분 | F12: 수량 | G12: 단위 | H12: 수량 | I12: 단위 | J12: 단가(원) | K12: 금액(원)
B13: ○ 보고서 인쇄비 | K13: =TRUNC(SUM(K14:K16), -3) -> 3368000
B14: - 내지(백상지, 10포인트, 10절, 50권) | F14: 200 | G14: 매 | J14: 15288 | K14: =F14*J14 -> 3057600
B15: - 표지(아트지, 10절, 50권, 2매) | F15: 1 | G15: 식 | J15: 290100 | K15: =F15*J15 -> 290100
B16: - 제본(10절, 무사무선철) | F16: 1 | G16: 식 | J16: 21160 | K16: =F16*J16 -> 21160
B18: Ⅱ-3. 주민 설명회 경비
B19: 구 분 | F19: 수량 | G19: 단위 | H19: 수량 | I19: 단위 | J19: 단가(원) | K19: 금액(원)
B20: ○ 주민 설명회 경비 | K20: =TRUNC(SUM(K21:K22), -3) -> 2700000
B21: - 회의비(설명회 자료 인쇄 등) | F21: 6 | G21: 회 | J21: 150000 | K21: =F21*J21 -> 900000
B22: - 사무용품비(현수막, 배너 등) | F22: 6 | G22: 회 | J22: 300000 | K22: =F22*J22 -> 1800000
B23: ※ 6개 권역 설명회
B25: Ⅱ-3. 포럼 및 워크숍 경비
B26: 구 분 | F26: 수량 | G26: 단위 | H26: 수량 | I26: 단위 | J26: 단가(원) | K26: 금액(원)
B27: 계 | K27: =SUM(K28+K32) -> 21380000
B28: ○ 포럼 경비 | K28: =SUM(K29:K31) -> 8690000
B29: - 사무용품비(현수막, 배너 등) | F29: 1 | G29: 식 | J29: 200000 | K29: =F29*J29 -> 200000
B30: - 강사비 | F30: 7 | G30: 명 | J30: 570000 | K30: =F30*J30 -> 3990000
B31: - 교재, 소모품 등 | F31: 150 | G31: 명 | J31: 30000 | K31: =F31*J31 -> 4500000
B32: ○ 워크숍 경비 | K32: =SUM(K33:K39) -> 12690000
B33: - 사무용품비(현수막, 배너 등) | F33: 1 | G33: 식 | J33: 290000 | K33: =F33*J33 -> 290000
B34: - 대관비 | F34: 1 | G34: 실 | H34: 2 | I34: 일 | J34: 1000000 | K34: =F34*H34*J34 -> 2000000
B35: - 숙박비 | F35: 50 | G35: 실 | H35: 1 | I35: 일 | J35: 70000 | K35: =F35*H35*J35 -> 3500000
B36: - 식비 | F36: 50 | G36: 명 | H36: 3 | I36: 식 | J36: 9000 | K36: =F36*H36*J36 -> 1350000
B37: - 강사비 | F37: 5 | G37: 명 | J37: 570000 | K37: =F37*J37 -> 2850000
B38: - 교재, 소모품 등 | F38: 50 | G38: 명 | J38: 30000 | K38: =F38*J38 -> 1500000
B39: - 여비(용역사) | F39: 8 | G39: 명 | H39: 1 | I39: 일 | J39: 150000 | K39: =F39*J39 -> 1200000
B40: ※ 「2025년도 지방자치인재개발원 강사수당 및 원고료 등 지급기준」강사수당 지급기준
B41: 강사수당 37만원(1급 2시간 기준), 이동시간 보상 12만원, 여비 8만원(운임,일비,식비) 산정
B42: ※ 공무원여비규정 별표2 적용(일비 25,000원, 숙박비 70,000원, 식비 25,000원, 운임 30,000원 적용)
B44: Ⅱ-4. 자문회의비
B45: 구 분 | F45: 수량 | G45: 단위 | H45: 수량 | I45: 단위 | J45: 단가(원) | K45: 금액(원)
...

Sheet 산출근거(계획면적 산정)
A1: ■ 계획면적(㎡) 산출근거
B4: 구분 | D4: 대상지(개소) | E4: 개소당 계획면적(㎡) | F4: 계획면적 합계(㎡)
B5: 시민참여형 정원 | D5: 80 | E5: 400 | F5: =D5*E5 -> 32000
B8: 공공형 정원 | D8: 20 | E8: 400 | F8: =D8*E8 -> 8000
B11: 계 | D11: 100 | E11: - | F11: =F5+F8 -> 40000
B14: 적용 계획면적 * 국토계획 품셈(245p) 환산계수 면적 세부내용예 따름 (5만㎡ 이하일 경우, 5만㎡ 적용) | F14: 50000

Sheet 산출근거(인쇄)
A1: ■ 인쇄비
B3: 인쇄비 산출근거 | D3: : 보고서 ( | E3: 50 | F3: )부 기준
B5: 가. 보고서 인쇄요금 요금(한국인터넷진흥원 2024 인쇄 기준단가 적용)
B6: 1) 경인쇄(마스타제판) 기준요금 | H6: 2) 표지가격
B7: 절 수 | C7: 지 질 | D7: 50부까지 | E7: 10부마다 | F7: 비 고 | H7: 1. 표지는 백상지 80g/m2이상을 사용하여야 하며, 단색인쇄의 경우에는 다음가격에 의한다.
B8: 8절 | C8: 백 상 지 | D8: 19340 | E8: 229 | H8: 가) 8절 책자:8절 백상지 10포인트 5매가격
B9: 10절 | C9: 백 상 지 | D9: 15288 | E9: 196 | F9: 적 용 | H9: 나) 10절 책자:8절 백상지 10포인트 5매가격
B10: 16절 | C10: 백 상 지 | D10: 10293 | E10: 125 | H10: 다) 16절 책자:8절 백상지 10포인트 3매가격
B11: 25절 | C11: 백 상 지 | D11: 7020 | E11: 100 | H11: 라) 25절 책자:10절 백상지 10포인트 3매가격
B12: 32절 | C12: 백 상 지 | D12: 5271 | E12: 68 | H12: 마) 32절 책자:16절 백상지 10포인트 3매가격
B13: ※ 10 포인트 주간작업 기준, 전자조판기준, 인쇄면당 | H13: 2. 기본1도 이외의 추가 색도에 대하여는 1색도당 2.5매를 기본 50부까지의 가격에 가산한다.
H14: 3. 아트지, 레자크지등을 사용할때는 추가1색도로 보며, 코팅을 할때에는 추가 2색도로 본다.
H15: 4. 중간크기 책자의 표지가격은 큰절수의 기준요금을 계산한다.
G16: ="(일금"&TEXT(D16,"[DBnum4]G/표준")&"원)" -> (일금영원) | H16: 5. 양장, 반양장등 특수표지로 제본할때에는 실비를 별도로 계상한다.
B18: 3) 보고서 인쇄비 산정
B19: - 백상지, 경인쇄, A4(10절), 200P | E19: : 10절백상지단가×면수(100면×양면))
D20: =D9 -> 15288 | E20: × ( | F20: 100 | G20: × | H20: 2 | I20: ) ＋ ( | J20: 0 | K20: × | L20: 0 | M20: × | N20: 0 | O20: × | P20: 0 | Q20: ) | R20: = | S20: =D20*(F20*H20)+(J20*L20*N20*P20) -> 3057600
B21: - 표지 : 아트지(50부) | E21: : 8절백상지단가×(5매＋2색도＋아트지＋코팅)×부수
D22: 19340 | E22: × ( | F22: 5 | G22: ＋ | H22: 2.5 | I22: ＋ | J22: 2.5 | K22: ＋ | L22: 2.5 | M22: × | N22: 2 | O22: ) × | P22: 1 | R22: = | S22: =D22*(F22+H22+J22+(L22*N22))*P22 -> 290100
B23: - 제본료 : 무사무선철적용 | E23: : 책자제본료 10절 무사무선철단가×면수×부수)
D24: 2.116 | E24: × ( | F24: 100 | G24: × | H24: 2 | I24: × | J24: 50 | K24: ) | R24: = | S24: =F24*D24*H24*J24 -> 21160
B25: - 계 | R25: = | S25: =ROUNDDOWN((S22+S20+S24),-3) -> 3368000

Sheet 노임단가
A1: ■ 엔지니어링 노임단가(2025년)
A2: 구 분 | B2: 노 무 비 | C2: 비 고
A3: 기술사 | B3: 452718
A4: 특급기술자 | B4: 358273
A5: 고급기술자 | B5: 300980
A6: 중급기술자 | B6: 284046
A7: 초급기술자 | B7: 223644
A8: 고급숙련기술자 | B8: 267012
A9: 중급숙련기술자 | B9: 240710
A10: 초급숙련기술자 | B10: 204392 | C10: '보조원' 단가 적용
A11: 기술사(측량) | B11: 429789
A12: 특급기술자(측량) | B12: 315285
A13: 고급기술자(측량) | B13: 280278
A14: 중급기술자(측량) | B14: 244289
A15: 초급기술자(측량) | B15: 207826
A16: 고급기능사(측량) | B16: 250450 | G16: ="(일금"&TEXT(D16,"[DBnum4]G/표준")&"원)" -> (일금영원)
A17: 중급기능사(측량) | B17: 227604
A18: 초급기능사(측량) | B18: 193697
A19: 고급기능사(지도제작) | B19: 258447
A20: 중급기능사(지도제작) | B20: 234179
A21: 초급기능사(지도제작) | B21: 192075
A22: 고급기능사(도화) | B22: 291056
A23: 중급기능사(도화) | B23: 229940
A24: 초급기능사(도화) | B24: 221287
A25: 특별인부 | B25: 221506
A26: 보통인부 | B26: 169804

Sheet 2-1.기본설계
A1: 공 종 | B1: 규 격 | C1: 수 량 | D1: 단위 | E1: 합 계 | G1: 재 료 비 | I1: 노 무 비 | K1: 경 비 | M1: 비 고
E2: 단 가 | F2: 금 액 | G2: 단 가 | H2: 금 액 | I2: 단 가 | J2: 금 액 | K2: 단 가 | L2: 금 액
A3: 2. 기본설계 | M3: 산근1
A5: 가. 공사비 요율에 의한 방법
A7: =보간!E2 -> : 정원 조성공사(조경) (도로분야 요율 적용)
A8: 1) 개 략 공 사 비 | C8: 1 | D8: 식 | E8: =보간!C4 -> 6.0363636e+09
A9: 2) 용역비 적용요율 | C9: 1 | D9: % | E9: =보간!H15 -> 3.41
A10: 3) 용역비 산출 | C10: 1 | D10: 식 | E10: =ROUNDDOWN(E8*(E9/100),-6) -> 205000000
A12: 소 계 | E12: =E10 -> 205000000
A13: 낙찰률 적용 | C13: 1 | D13: 식 | E13: =ROUNDDOWN(E12*O13,-5) -> 171600000 | M13: 단위절사 | O13: 0.837419
A15: 나. 직 접 경 비
A16: 1) 조감도 | C16: 1 | D16: 식 | E16: 7000000
A17: 소 계 | E17: =E16 -> 7000000
E19: =E18 -> 0
A20: 낙찰률 적용 | C20: 1 | D20: 식 | E20: =ROUNDDOWN(E16*O13,-5) -> 5800000 | M20: 단위절사
A22: 합 계 (낙찰률 적용) | E22: =E13+E20 -> 177400000 | O22: =E12+E17 -> 212000000
E24: 0

Sheet 보간
B2: 공사비요율에 의한 방식(직선보간법 적용) | E2: : 정원 조성공사(조경) (도로분야 요율 적용)
A4: x : | B4: 당해금액 | C4: =F4/1.1 -> 6.0363636e+09 | E4: 공사비(VAT 포함) : | F4: 6640000000
A5: x1 : | B5: 큰금액 | C5: 10000000000
A6: x2 : | B6: 작은금액 | C6: 5000000000 | E6: =B9 -> 작은금액요율 | F6: - | G6: ( | H6: =B4 -> 당해금액 | I6: - | J6: =B6 -> 작은금액 | K6: ) | L6: x | M6: ( | N6: =B9 -> 작은금액요율 | O6: - | P6: =B10 -> 큰금액요율 | Q6: )
J7: =B5 -> 큰금액 | L7: - | M7: =B6 -> 작은금액
A8: y : | B8: 당해공사요율 | C8: =ROUNDDOWN(H10-J10,2) -> 2.75
A9: y1 : | B9: 작은금액요율 | C9: 2.82 | F9: = | H9: =C9 -> 2.82 | I9: - | J9: =(C4-C6)*(C9-C10) -> 3.42e+08 | L9: ÷ | M9: =C5-C6 -> 5000000000
A10: y2 : | B10: 큰금액요율 | C10: 2.49 | F10: = | H10: =C9 -> 2.82 | I10: - | J10: =J9/M9 -> 0.0684
F11: = | H11: =H10-J10 -> 2.7516
D13: 1.3 | E13: 1 | F13: → | H13: =ROUNDDOWN(H11*E13,2) -> 2.75
E14: 용역비 요율 할증 | H14: 1.24 | I14: (타당성 조사를 시행하지 않은 기본설계 발주 : 기본설계 요율의 1.24배)
E15: 기본설계 요율 | H15: =ROUNDDOWN(H13*H14,2) -> 3.41
B23: *참조 : 산업통상자원부 고시 제2024-217호, 2024년 12월 31일, 엔지니어링사업대가의 기준
B24: 별표 1 : 건설부문의 요율
B25: 제13조(요율) ① 공사비요율에 의한 방식을 적용할 경우 건설부문의 요율은 별표 1과 같고, 통신부문의 요율은 별표 2와 같으며, 산업플랜트부문의 요율은 별표 3과 같고, 기본설계ㆍ실시설계 및 공사감리 업무단위별로 구분하여 적용한다. ② 제1항에도 불구하고 업무단계별로 구분하여 발주하지 않는 기본설계와 실시설계 요율은 다음 각 호와 같다. 1. 기본설계와 실시설계를 동시에 발주하는 경우에는 다음 각목에 따라 적용한다. 가. 건설부문의 경우 해당 실시설계요율의 1.45배 나. 통신부문의 경우 해당 실시설계요율의 1.27배 다. 산업플랜트부문의 경우 해당 실시설계요율의 1.31배 2. 타당성조사와 기본설계를 동시에 발주하는 경우에는 다음 각 목에 따라 적용한다. 가. 건설부문의 경우 해당 기본설계 요율의 1.35배 나. 통신부문의 경우 해당 기본설계 요율의 1.18배 다. 산업플랜트부문의 경우 해당 기본설계 요율의 1.22배 3. 기본설계를 시행하지 않은 실시설계를 발주하는 경우에는 다음 각 목에 따라 적용한다. 가. 건설부문의 경우 해당 실시설계 요율의 1.35배 나. 통신부문의 경우 해당 실시설계 요율의 1.18배 다. 산업플랜트부문의 경우 해당 실시설계 요율의 1.22배 4. 타당성 조사를 시행하지 않은 기본설계를 발주하는 경우에는 다음 각 목에 따라 적용한다. 가. 건설부문의 경우 해당 기본설계 요율의 1.24배 나. 통신부문의 경우 해당 기본설계 요율의 1.09배 다. 산업플랜트부문의 경우 해당 기본설계 요율의 1.12배
H45: ※ 요율표가 작성되지 않은 다른 분야는 도로분야의 요율을 적용한다.

Sheet 1-2.직접경비(기정) (2)
B1: 직 접 경 비 산 출 내 역 서
B3: Ⅱ. 직접경비
B4: 구 분 | F4: 금액(원) | N4: =F8+F9 -> 34980000
B5: 계 | F5: =SUM(F6:K9) -> 41048000 | N5: =N4*0.1 -> 3498000
B6: 인쇄비 | F6: =K13 -> 3368000 | N6: =N4+N5 -> 38478000
B7: 주민설명회 경비 | F7: =K20 -> 2700000
B8: 포럼 및 워크숍 경비 | F8: =K27 -> 21380000
B9: 자문회의비 | F9: =K46 -> 13600000
B11: Ⅱ-1. 인쇄비
B12: 구 분 | F12: 수량 | G12: 단위 | H12: 수량 | I12: 단위 | J12: 단가(원) | K12: 금액(원)
B13: ○ 보고서 인쇄비 | K13: =TRUNC(SUM(K14:K16), -3) -> 3368000
B14: - 내지(백상지, 10포인트, 10절, 50권) | F14: 200 | G14: 매 | J14: 15288 | K14: =F14*J14 -> 3057600
B15: - 표지(아트지, 10절, 50권, 2매) | F15: 1 | G15: 식 | J15: 290100 | K15: =F15*J15 -> 290100
B16: - 제본(10절, 무사무선철) | F16: 1 | G16: 식 | J16: 21160 | K16: =F16*J16 -> 21160
B18: Ⅱ-3. 주민 설명회 경비
B19: 구 분 | F19: 수량 | G19: 단위 | H19: 수량 | I19: 단위 | J19: 단가(원) | K19: 금액(원)
B20: ○ 주민 설명회 경비 | K20: =TRUNC(SUM(K21:K22), -3) -> 2700000
B21: - 회의비(설명회 자료 인쇄 등) | F21: 6 | G21: 회 | J21: 150000 | K21: =F21*J21 -> 900000
B22: - 사무용품비(현수막, 배너 등) | F22: 6 | G22: 회 | J22: 300000 | K22: =F22*J22 -> 1800000
B23: ※ 6개 권역 설명회
B25: Ⅱ-3. 포럼 및 워크숍 경비
B26: 구 분 | F26: 수량 | G26: 단위 | H26: 수량 | I26: 단위 | J26: 단가(원) | K26: 금액(원)
B27: 계 | K27: =SUM(K28+K32) -> 21380000
B28: ○ 포럼 경비 | K28: =SUM(K29:K31) -> 8690000
B29: - 사무용품비(현수막, 배너 등) | F29: 1 | G29: 식 | J29: 200000 | K29: =F29*J29 -> 200000
B30: - 강사비 | F30: 7 | G30: 명 | J30: 570000 | K30: =F30*J30 -> 3990000
B31: - 교재, 소모품 등 | F31: 150 | G31: 명 | J31: 30000 | K31: =F31*J31 -> 4500000
B32: ○ 워크숍 경비 | K32: =SUM(K33:K39) -> 12690000
B33: - 사무용품비(현수막, 배너 등) | F33: 1 | G33: 식 | J33: 290000 | K33: =F33*J33 -> 290000
B34: - 대관비 | F34: 1 | G34: 실 | H34: 2 | I34: 일 | J34: 1000000 | K34: =F34*H34*J34 -> 2000000
B35: - 숙박비 | F35: 50 | G35: 실 | H35: 1 | I35: 일 | J35: 70000 | K35: =F35*H35*J35 -> 3500000
B36: - 식비 | F36: 50 | G36: 명 | H36: 3 | I36: 식 | J36: 9000 | K36: =F36*H36*J36 -> 1350000
B37: - 강사비 | F37: 5 | G37: 명 | J37: 570000 | K37: =F37*J37 -> 2850000
B38: - 교재, 소모품 등 | F38: 50 | G38: 명 | J38: 30000 | K38: =F38*J38 -> 1500000
B39: - 여비(용역사) | F39: 8 | G39: 명 | H39: 1 | I39: 일 | J39: 150000 | K39: =F39*J39 -> 1200000
B40: ※ 「2025년도 지방자치인재개발원 강사수당 및 원고료 등 지급기준」강사수당 지급기준
B41: 강사수당 37만원(1급 2시간 기준), 이동시간 보상 12만원, 여비 8만원(운임,일비,식비) 산정
B42: ※ 공무원여비규정 별표2 적용(일비 25,000원, 숙박비 70,000원, 식비 25,000원, 운임 30,000원 적용)
B44: Ⅱ-4. 자문회의비
B45: 구 분 | F45: 수량 | G45: 단위 | H45: 수량 | I45: 단위 | J45: 단가(원) | K45: 금액(원)
...
